Workbook

Sheet 26.9月당월_면장
A2: 2026년 09월 수출마감내역
A4: 대신금속㈜
A5: 거래처 | B5: 공장구분 | C5: INVOICE NO | D5: 수출신고필증 NO. | E5: BL일자 | F5: 환율 | G5: 금 액
G6: 금액(외화) | H6: 금 액(원화) | I6: 업 체 별 합 계 | K6: 비 고
A7: 툴링비 | B7: 마산1 | C7: DSM2609-SAMPLE1 | D7: 툴링비 | E7: 46276 | F7: =IFERROR(VLOOKUP(E7,환율!A:B,2,0),1350) -> 1338.2 | G7: 5 | H7: =ROUNDDOWN(F7*G7,0) -> 6691 | I7: 0 | J7: 0 | K7: 머큐리 무상 샘플 | L7: =SUM(#REF!) -> #REF!
A8: 앨리슨 관세 | B8: 마산2 | C8: 8월 오기재 관세 차액분 (DSM2608-AL03(관세) | D8: 관세 | E8: 46256 | F8: =IFERROR(VLOOKUP(E8,환율!A:B,2,0),1350) -> 1393 | G8: -4223.11 | H8: =ROUNDDOWN(F8*G8,0) -> -5882792 | K8: 정확한 금액은 10일 이후 국세청에서 확인 가능
B9: 마산2 | C9: DSM2608-AL05(관세) | E9: 46268 | F9: =IFERROR(VLOOKUP(E9,환율!A:B,2,0),1350) -> 1369.4 | G9: 92492.41 | H9: =ROUNDDOWN(F9*G9,0) -> 126659106
B10: 마산2 | C10: DSM2609-AL01(관세) | E10: 46272 | F10: 1355.2 | G10: 2837.63 | H10: =ROUNDDOWN(F10*G10,0) -> 3845556
B11: 마산2 | C11: DSM2609-AL02(관세) | E11: 46279 | F11: 1346.4 | G11: 5125.44 | H11: =ROUNDDOWN(F11*G11,0) -> 6900892
B12: 마산2 | C12: DSM2609-AL03(관세) | E12: 46283 | F12: =IFERROR(VLOOKUP(E12,환율!A:B,2,0),1350) -> 1380.3 | G12: 96202.88 | H12: =ROUNDDOWN(F12*G12,0) -> 132788835
B13: 마산2 | C13: DSM2609-AL04(관세) | E13: 46292 | F13: 1360 | G13: 1316.67 | H13: =ROUNDDOWN(F13*G13,0) -> 1790671
B14: 마산2 | C14: DSM2609-AL06(관세) | E14: 46294 | F14: 1360 | G14: 88553.23 | H14: =ROUNDDOWN(F14*G14,0) -> 120432392
B15: 마산2 | C15: DSM2609-AL07(관세) | E15: 46289 | F15: 1360 | G15: 5675.25 | H15: =ROUNDDOWN(F15*G15,0) -> 7718340 | I15: =SUM(G8:G15) -> 287980.4 | J15: =SUM(H8:H15) -> 394253000
A16: DOMETIC | B16: 마산1 | C16: DSM2609-SE01 | D16: 41072-26-702473X | E16: 46272 | F16: =IFERROR(VLOOKUP(E16,환율!A:B,2,0),1350) -> 1355.2 | G16: 576 | H16: =ROUNDDOWN(F16*G16,0) -> 780595 | I16: =SUM(G16) -> 576 | J16: =SUM(H16) -> 780595
A17: POLARIS | B17: 마산1 | C17: 2608P02 | D17: 41072-26-702010X | E17: 46267 | F17: =IFERROR(VLOOKUP(E17,환율!A:B,2,0),1350) -> 1370.3 | G17: 47561.04 | H17: =ROUNDDOWN(F17*G17,0) -> 65172893 | L17: =SUM(G17:G19) -> 142740.72 | M17: =SUM(H17:H19) -> 194301386
B18: 마산1 | C18: 2608P04 | D18: 41072-26-702183X | E18: 46270 | F18: =IFERROR(VLOOKUP(E18,환율!A:B,2,0),1350) -> 1359.5 | G18: 32788.8 | H18: =ROUNDDOWN(F18*G18,0) -> 44576373
B19: 마산1 | C19: 2608P06 | D19: 41072-26-702340X | E19: 46272 | F19: =IFERROR(VLOOKUP(E19,환율!A:B,2,0),1350) -> 1355.2 | G19: 62390.88 | H19: =ROUNDDOWN(F19*G19,0) -> 84552120
B20: 마산1 | C20: 2609P02 | D20: 41072-26-702487X | E20: 46293 | F20: =IFERROR(VLOOKUP(E20,환율!A:B,2,0),1350) -> 1352 | G20: 38786.4 | H20: =ROUNDDOWN(F20*G20,0) -> 52439212
B21: 마산1 | C21: 2609P04 | D21: 41072-26-702638X | E21: 46293 | F21: =IFERROR(VLOOKUP(E21,환율!A:B,2,0),1350) -> 1352 | G21: 53401.68 | H21: =ROUNDDOWN(F21*G21,0) -> 72199071 | I21: =SUM(G17:G21) -> 234928.8 | J21: =SUM(H17:H21) -> 318939669
A22: MERCURY | B22: 마산1 | C22: DSM2608-04 | D22: 41072-26-702170X | E22: 46267 | F22: =IFERROR(VLOOKUP(E22,환율!A:B,2,0),1350) -> 1370.3 | G22: 20779.32 | H22: =ROUNDDOWN(F22*G22,0) -> 28473902 | L22: =SUM(G22:G39) -> 869098.56 | M22: =SUM(H22:H39) -> 1180538559
B23: 마산1 | C23: DSM2608-05 | D23: 41072-26-702171X | E23: 46276 | F23: =IFERROR(VLOOKUP(E23,환율!A:B,2,0),1350) -> 1338.2 | G23: 33829.92 | H23: =ROUNDDOWN(F23*G23,0) -> 45271198
B24: 마산1 | C24: DSM2608-06 | D24: 41072-26-702073X | E24: 46266 | F24: =IFERROR(VLOOKUP(E24,환율!A:B,2,0),1350) -> 1373.6 | G24: 62017.4 | H24: =ROUNDDOWN(F24*G24,0) -> 85187100
B25: 마산1 | C25: DSM2608-07 | D25: 41072-26-702074X | E25: 46266 | F25: =IFERROR(VLOOKUP(E25,환율!A:B,2,0),1350) -> 1373.6 | G25: 102197.76 | H25: =ROUNDDOWN(F25*G25,0) -> 140378843
B26: 마산1 | C26: DSM2608-08 | D26: 41072-26-702172X | E26: 46276 | F26: =IFERROR(VLOOKUP(E26,환율!A:B,2,0),1350) -> 1338.2 | G26: 6048 | H26: =ROUNDDOWN(F26*G26,0) -> 8093433
B27: 마산1 | C27: DSM2608-09 | D27: 41072-26-702075X | E27: 46295 | F27: =IFERROR(VLOOKUP(E27,환율!A:B,2,0),1350) -> 1358.4 | G27: 6267.8 | H27: =ROUNDDOWN(F27*G27,0) -> 8514179
B28: 마산1 | C28: DSM2608-10 | D28: 41072-26-702173X | E28: 46267 | F28: =IFERROR(VLOOKUP(E28,환율!A:B,2,0),1350) -> 1370.3 | G28: 61116.6 | H28: =ROUNDDOWN(F28*G28,0) -> 83748076
B29: 마산1 | C29: DSM2608-11 | D29: 41072-26-702174X | E29: 46276 | F29: =IFERROR(VLOOKUP(E29,환율!A:B,2,0),1350) -> 1338.2 | G29: 60142.08 | H29: =ROUNDDOWN(F29*G29,0) -> 80482131
B30: 마산1 | C30: DSM2608-12 | D30: 41072-26-702175X | E30: 46291 | F30: =IFERROR(VLOOKUP(E30,환율!A:B,2,0),1350) -> 1360 | G30: 102197.76 | H30: =ROUNDDOWN(F30*G30,0) -> 138988953
B31: 마산1 | C31: DSM2608-13 | D31: 41072-26-702076X | E31: 46276 | F31: =IFERROR(VLOOKUP(E31,환율!A:B,2,0),1350) -> 1338.2 | G31: 103247.84 | H31: =ROUNDDOWN(F31*G31,0) -> 138166259
B32: 마산1 | C32: DSM2608-14 | D32: 41072-26-702176X | E32: 46276 | F32: =IFERROR(VLOOKUP(E32,환율!A:B,2,0),1350) -> 1338.2 | G32: 9275.84 | H32: =ROUNDDOWN(F32*G32,0) -> 12412929
B33: 마산1 | C33: DSM2608-15 | D33: 41072-26-702306X | E33: 46288 | F33: =IFERROR(VLOOKUP(E33,환율!A:B,2,0),1350) -> 1360 | G33: 55428.82 | H33: =ROUNDDOWN(F33*G33,0) -> 75383195
B34: 마산1 | C34: DSM2608-16 | D34: 41072-26-702307X | E34: 46285 | F34: =IFERROR(VLOOKUP(E34,환율!A:B,2,0),1350) -> 1380.3 | G34: 31631.6 | H34: =ROUNDDOWN(F34*G34,0) -> 43661097
... B46: 마산1 | C46: DSM2609-12 | D46: 41072-26-201636X | E46: 46293 | F46: =IFERROR(VLOOKUP(E46,환율!A:B,2,0),1350) -> 1352 | G46: 12956.58 | H46: =ROUNDDOWN(F46*G46,0) -> 17517296
B47: 마산1 | C47: DSM2609-21 | D47: 41072-26-702580X | E47: 46280 | F47: =IFERROR(VLOOKUP(E47,환율!A:B,2,0),1350) -> 1345.3 | G47: 6855.3 | H47: =ROUNDDOWN(F47*G47,0) -> 9222435 | I47: =SUM(G22:G47) -> 1207026.5 | J47: =SUM(H22:H47) -> 1641291737 | L47: =+I47+I50 -> 1457984.9 | M47: =+J47+J50 -> 1980039885
A48: MERCURY CHINA | B48: 마산1 | C48: DSM2609-MC01 | D48: 41072-26-702435X | E48: 46274 | F48: =IFERROR(VLOOKUP(E48,환율!A:B,2,0),1350) -> 1341.1 | G48: 85777.44 | H48: =ROUNDDOWN(F48*G48,0) -> 115036124
B49: 마산1 | C49: DSM2609-MC02 | D49: 41072-26-702561X | E49: 46280 | F49: =IFERROR(VLOOKUP(E49,환율!A:B,2,0),1350) -> 1345.3 | G49: 63542.88 | H49: =ROUNDDOWN(F49*G49,0) -> 85484236
B50: 마산1 | C50: DSM2609-MC03 | D50: 41072-26-702728X | E50: 46292 | F50: =IFERROR(VLOOKUP(E50,환율!A:B,2,0),1350) -> 1360 | G50: 101638.08 | H50: =ROUNDDOWN(F50*G50,0) -> 138227788 | I50: =SUM(G48:G50) -> 250958.4 | J50: =SUM(H48:H50) -> 338748148
A51: BERGEN ENGINE | B51: 마산1 | C51: DSM2609-R01 | D51: 41072-26-702484X | E51: 46276 | F51: 1350 | G51: =H51/1350 -> 17339.159 | H51: 23407864 | I51: =SUM(G51:G51) -> 17339.159 | J51: =SUM(H51:H51) -> 23407864 | K51: 원화수출(1,350원 기준원화 적용)
A52: ALLISON | B52: 마산2 | C52: DSM2608-AL05 | D52: 41072-26-702341X | E52: 46278 | F52: =IFERROR(VLOOKUP(E52,환율!A:B,2,0),1350) -> 1338.2 | G52: 390865.54 | H52: =ROUNDDOWN(F52*G52,0) -> 523056265 | L52: =SUM(G52:G52) -> 390865.54 | M52: =SUM(H52:H52) -> 523056265
B53: 마산2 | C53: DSM2609-AL01 | D53: 41072-26-702438X | E53: 46272 | F53: =IFERROR(VLOOKUP(E53,환율!A:B,2,0),1350) -> 1355.2 | G53: 11856 | H53: =ROUNDDOWN(F53*G53,0) -> 16067251
...

Sheet 26.9月이월_면장
A3: 2026년 09월 수출마감 이월내역
A5: 대신금속㈜ | C5: 매출마감일 기준 BL 미발행 | D5: ※ 당월출하 익월선적
A6: 거래처 | B6: 공장구분 | C6: INVOICE NO | D6: 수출신고필증 NO. | E6: BL일자 | F6: 환율 | G6: 금 액
G7: 금액(외화) | H7: 금 액(원화) | I7: 업 체 별 합 계 | K7: 비 고
A8: POLARIS | B8: 마산1 | C8: 2609P01 | D8: 41072-26-702486X | E8: 46296 | F8: =IFERROR(VLOOKUP(E8,환율!A:B,2,0),1350) -> 1355.7 | G8: 43675.2 | H8: =ROUNDDOWN(F8*G8,0) -> 59210468
B9: 마산1 | C9: 2609P03 | D9: 41072-26-702529X | E9: 46296 | F9: =IFERROR(VLOOKUP(E9,환율!A:B,2,0),1350) -> 1355.7 | G9: 19041.39 | H9: =ROUNDDOWN(F9*G9,0) -> 25814412
B10: 마산1 | C10: 2609P05 | D10: 41072-26-702492X | E10: 46296 | F10: =IFERROR(VLOOKUP(E10,환율!A:B,2,0),1350) -> 1355.7 | G10: 34799.04 | H10: =ROUNDDOWN(F10*G10,0) -> 47177058
B11: 마산1 | C11: 2609P06 | D11: 41072-26-702771X | E11: 46296 | F11: =IFERROR(VLOOKUP(E11,환율!A:B,2,0),1350) -> 1355.7 | G11: 55229.04 | H11: =ROUNDDOWN(F11*G11,0) -> 74874009
B12: 마산1 | C12: 2609P07 | D12: 41072-26-702488X | E12: 46296 | F12: =IFERROR(VLOOKUP(E12,환율!A:B,2,0),1350) -> 1355.7 | G12: 274.75 | H12: =ROUNDDOWN(F12*G12,0) -> 372478 | I12: =SUM(G8:G12) -> 153019.42 | J12: =SUM(H8:H12) -> 207448425
A13: MERCURY | B13: 마산1 | C13: DSM2609-05 | D13: 41072-26-702562X | E13: 46296 | F13: =IFERROR(VLOOKUP(E13,환율!A:B,2,0),1350) -> 1355.7 | G13: 35148.48 | H13: =ROUNDDOWN(F13*G13,0) -> 47650794
B14: 마산1 | C14: DSM2609-06 | D14: 41072-26-702563X | E14: 46296 | F14: =IFERROR(VLOOKUP(E14,환율!A:B,2,0),1350) -> 1355.7 | G14: 92794.34 | H14: =ROUNDDOWN(F14*G14,0) -> 125801286
B15: 마산1 | C15: DSM2609-07 | D15: 41072-26-702564X | E15: 46296 | F15: =IFERROR(VLOOKUP(E15,환율!A:B,2,0),1350) -> 1355.7 | G15: 60142.08 | H15: =ROUNDDOWN(F15*G15,0) -> 81534617
B16: 마산1 | C16: DSM2609-10 | D16: 41072-26-702566X | E16: 46296 | F16: =IFERROR(VLOOKUP(E16,환율!A:B,2,0),1350) -> 1355.7 | G16: 6636.72 | H16: =ROUNDDOWN(F16*G16,0) -> 8997401
B17: 마산1 | C17: DSM2609-13 | D17: 41072-26-201637X | E17: 46296 | F17: =IFERROR(VLOOKUP(E17,환율!A:B,2,0),1350) -> 1355.7 | G17: 70099.56 | H17: =ROUNDDOWN(F17*G17,0) -> 95033973
B18: 마산1 | C18: DSM2609-14 | D18: 41072-26-201638X | E18: 46296 | F18: =IFERROR(VLOOKUP(E18,환율!A:B,2,0),1350) -> 1355.7 | G18: 60142.08 | H18: =ROUNDDOWN(F18*G18,0) -> 81534617
B19: 마산1 | C19: DSM2609-15 | D19: 41072-26-201639X | E19: 46296 | F19: =IFERROR(VLOOKUP(E19,환율!A:B,2,0),1350) -> 1355.7 | G19: 100448.32 | H19: =ROUNDDOWN(F19*G19,0) -> 136177787
B20: 마산1 | C20: DSM2609-16 | D20: 41072-26-201640X | E20: 46296 | F20: =IFERROR(VLOOKUP(E20,환율!A:B,2,0),1350) -> 1355.7 | G20: 5281.92 | H20: =ROUNDDOWN(F20*G20,0) -> 7160698
B21: 마산1 | C21: DSM2609-18 | D21: 41072-26-702718X | E21: 46296 | F21: =IFERROR(VLOOKUP(E21,환율!A:B,2,0),1350) -> 1355.7 | G21: 94218.78 | H21: =ROUNDDOWN(F21*G21,0) -> 127732400
B22: 마산1 | C22: DSM2609-19 | D22: 41072-26-702719X | E22: 46296 | F22: =IFERROR(VLOOKUP(E22,환율!A:B,2,0),1350) -> 1355.7 | G22: 60142.08 | H22: =ROUNDDOWN(F22*G22,0) -> 81534617
B23: 마산1 | C23: DSM2609-20 | D23: 41072-26-702720X | E23: 46296 | F23: =IFERROR(VLOOKUP(E23,환율!A:B,2,0),1350) -> 1355.7 | G23: 51098.88 | H23: =ROUNDDOWN(F23*G23,0) -> 69274751 | I23: =SUM(G13:G23) -> 636153.24 | J23: =SUM(H13:H23) -> 862432941
A24: MERCURY CHINA | B24: 마산1 | E24: 46296 | F24: =IFERROR(VLOOKUP(E24,환율!A:B,2,0),1350) -> 1355.7 | H24: =ROUNDDOWN(F24*G24,0) -> 0 | I24: =SUM(G24) -> 0 | J24: =SUM(H24:H24) -> 0 | L24: =+I23+I24 -> 636153.24 | M24: =+J23+J24 -> 862432941
A25: BERGEN ENGINE | B25: 마산1 | C25: DSM2609-R02 | D25: 41072-26-201642X | E25: 46296 | F25: 1350 | G25: =H25/F25 -> 96692.261 | H25: 130534552 | K25: 원화수출
B26: 마산1 | C26: DSM2609-R03 | D26: 41072-26-702849X | E26: 46296 | F26: 1350 | G26: =H26/F26 -> 10500.984 | H26: 14176329 | K26: 원화수출
B27: 마산1 | C27: DSM2609-R04 | D27: 41072-26-702795X | E27: 46296 | F27: 1350 | G27: =H27/F27 -> 55053.384 | H27: 74322068 | I27: =SUM(G25:G27) -> 162246.63 | J27: =SUM(H25:H27) -> 219032949 | K27: 원화수출
A28: ALLISON | B28: 마산2 | C28: DSM2608-AL06 | D28: 41072-26-702346X | E28: 46296 | F28: =IFERROR(VLOOKUP(E28,환율!A:B,2,0),1350) -> 1355.7 | G28: 97949.28 | H28: =ROUNDDOWN(F28*G28,0) -> 132789838 | K28: 센타하우징 15개 출하 8월 출하 건으로 10월 이월
B29: 마산2 | C29: DSM2609-AL09 | D29: 41072-26-702792X | E29: 46296 | F29: =IFERROR(VLOOKUP(E29,환율!A:B,2,0),1350) -> 1355.7 | G29: 444624 | H29: =ROUNDDOWN(F29*G29,0) -> 602776756 | I29: =SUM(G28:G29) -> 542573.28 | J29: =SUM(H28:H29) -> 735566594
A30: SAM | B30: 마산3 | C30: DSM2609-SM04 | D30: 41129-26-090282X | E30: 46296 | F30: =IFERROR(VLOOKUP(E30,환율!A:B,2,0),1350) -> 1355.7 | G30: 27068.72 | H30: =ROUNDDOWN(F30*G30,0) -> 36697063 | I30: =SUM(G30:G30) -> 27068.72 | J30: =SUM(H30:H30) -> 36697063
A31: EMERSON | B31: 마산3 | C31: DSM2609-EM07 | D31: 41072-26-702539X | E31: 46296 | F31: =IFERROR(VLOOKUP(E31,환율!A:B,2,0),1350) -> 1355.7 | G31: 21565 | H31: =ROUNDDOWN(F31*G31,0) -> 29235670
B32: 마산3 | C32: DSM2609-EM09 | D32: 41072-26-702756X | E32: 46296 | F32: =IFERROR(VLOOKUP(E32,환율!A:B,2,0),1350) -> 1355.7 | G32: 27888 | H32: =ROUNDDOWN(F32*G32,0) -> 37807761 | I32: =SUM(G31:G32) -> 49453 | J32: =SUM(H31:H32) -> 67043431
A33: AMAT | B33: 마산3 | C33: DSM2609-AM04 | E33: 46296 | F33: =IFERROR(VLOOKUP(E33,환율!A:B,2,0),1350) -> 1355.7 | G33: 52188.8 | H33: =ROUNDDOWN(F33*G33,0) -> 70752356 | I33: =SUM(G33:G33) -> 52188.8 | J33: =SUM(H33:H33) -> 70752356
A34: 합 계 | G34: =SUM(G8:G33) -> 1622703.1 | H34: =SUM(H8:H33) -> 2198973759 | I34: =SUM(I11:I33) -> 1622703.1 | J34: =SUM(J11:J33) -> 2198973759
A35: 2026년 9월 | D35: 공장별 매출 [이월] 당월출하 익월선적분 | G35: 마산1공장 | I35: =SUM(I11:I27) -> 951419.29 | J35: =SUM(J11:J27) -> 1288914315
G36: 마산2공장 | I36: =SUM(I29:I29) -> 542573.28 | J36: =SUM(J29:J29) -> 735566594
G37: 마산3공장 | I37: =SUM(I30:I33) -> 128710.52 | J37: =SUM(J30:J33) -> 174492850
G38: 마산1,2,3공장 | I38: =SUM(I35:I37) -> 1622703.1 | J38: =SUM(J35:J37) -> 2198973759
A39: 9월 매출 + 이월 | I39: =SUM('26.9月당월_면장'!I76+I38) -> 5155833.9 | J39: =SUM('26.9月당월_면장'!J76+J38) -> 6993611719
I83: =SUM(I61:I79) -> 0 | J83: =SUM(J61:J79) -> 0
G85: =SUM(G21:G84) -> 2661693.3 | H85: =SUM(H21:H84) -> 3606607920
D92: 2월 이월금액 | G92: 2월 이월금액 | I92: =#REF!+#REF!+#REF!+G38+G39+#REF!+G40+G41+G42+G43+G44+G45+G46+G47+G57+G63+G64+G65+G66+G68+G72+G75+G76+G77 -> #REF! | J92: =#REF!+#REF!+#REF!+H38+H39+#REF!+H40+H41+H42+H43+H44+H45+H46+H47+H57+H63+H64+H65+H66+H68+H72+H75+H76+H77 -> #REF!
G93: 3월 출하 금액 | I93: =I89-I92 -> #REF! | J93: =J89-J92 -> #REF!
...

Sheet 26.9月라인별
A1: 2026년 7월 수출매출(프로젝트별 실적금액)
A2: 3월 출하 | L2: 해외영업팀
A3: 업체명 | B3: 소재비 | F3: 소재합계 | G3: 가공1 | H3: 가공2 | I3: 가공3 | J3: 기타 | K3: 합 계 | L3: 비 고
B4: 사형 | C4: 자동 | D4: 금형1 (앨리슨외) | E4: 금형2 (앨리슨)
A5: Allison | B5: 0 | C5: 59662000 | E5: 9.1670839e+08 | F5: =SUM(B5:E5) -> 9.7637039e+08 | G5: 6.7409722e+08 | H5: 0 | I5: 0 | K5: =SUM(F5:J5) -> 1650467610
A6: Mercury | B6: 0 | C6: 3195133.9 | D6: 1.1601496e+09 | F6: =SUM(B6:E6) -> 1.1633447e+09 | G6: 2.5283622e+08 | H6: 1.7086111e+08 | I6: 0 | K6: =SUM(F6:J6) -> 1.5870421e+09
A7: Polaris | C7: 0 | D7: 2.6948131e+08 | F7: =SUM(B7:E7) -> 2.6948131e+08 | G7: 0 | H7: 1.1478327e+08 | I7: 0 | K7: =SUM(F7:J7) -> 3.8426458e+08
A8: Emerson | B8: 0 | C8: 0 | D8: 45203106 | F8: =SUM(B8:E8) -> 45203106 | G8: 0 | H8: 21369007 | I8: 5758997.2 | K8: =SUM(F8:J8) -> 72331110
A9: Mic | B9: 100365532 | C9: 0 | D9: 0 | F9: =SUM(B9:E9) -> 100365532 | G9: 0 | H9: 0 | I9: 29841185 | K9: =SUM(F9:J9) -> 130206717
A10: Sam | B10: 77808900 | C10: 0 | D10: 0 | F10: =SUM(B10:E10) -> 77808900 | G10: 0 | H10: 1200000 | I10: 930000 | K10: =SUM(F10:J10) -> 79938900
A11: Atlas Copco | B11: 53213400 | C11: 0 | D11: 0 | F11: =SUM(B11:E11) -> 53213400 | H11: 0 | I11: 11365800 | K11: =SUM(F11:J11) -> 64579200
A12: Bergen engine | B12: 23459331 | C12: 41356010 | D12: 0 | F12: =SUM(B12:E12) -> 64815341 | G12: 0 | H12: 6635952 | I12: 84879381 | K12: =SUM(F12:J12) -> 156330674
A13: Dometic | B13: 0 | C13: 0 | D13: 16099118 | F13: =SUM(B13:E13) -> 16099118 | G13: 0 | H13: 534016 | I13: 0 | K13: =SUM(F13:J13) -> 16633134
A14: 합 계 | B14: =SUM(B5:B13) -> 2.5484716e+08 | C14: =SUM(C5:C13) -> 1.0421314e+08 | D14: =SUM(D5:D13) -> 1.4909331e+09 | E14: =SUM(E5:E13) -> 9.1670839e+08 | F14: =SUM(B14:E14) -> 2.7667018e+09 | G14: =SUM(G5:G13) -> 9.2693344e+08 | H14: =SUM(H5:H13) -> 3.1538336e+08 | I14: =SUM(I5:I13) -> 1.3277536e+08 | J14: =SUM(J5:J13) -> 0 | K14: =SUM(F14:J14) -> 4.141794e+09
A15: 3월 매출 | L15: 해외영업팀
A16: 업체명 | B16: 소재비 | F16: 소재합계 | G16: 가공1 | H16: 가공2 | I16: 가공3 | J16: 기타 | K16: 합 계 | L16: 비 고
B17: 사형 | C17: 자동 | D17: 금형1 (앨리슨외) | E17: 금형2 (앨리슨)
A18: Allison | B18: 0 | C18: 59662000 | E18: 9.1670839e+08 | F18: =SUM(B18:E18) -> 9.7637039e+08 | G18: 6.7409722e+08 | H18: 0 | I18: 0 | K18: =SUM(F18:J18) -> 1650467610
A19: Mercury | B19: 0 | C19: 3195133.9 | D19: 8.5854141e+08 | F19: =SUM(B19:E19) -> 8.6173655e+08 | G19: 1.8122543e+08 | H19: 1.2245587e+08 | I19: 0 | K19: =SUM(F19:J19) -> 1165417848
A20: Polaris | F20: =SUM(B20:E20) -> 0 | K20: =SUM(F20:J20) -> 0
A21: Emerson | F21: =SUM(B21:E21) -> 0 | K21: =SUM(F21:J21) -> 0
A22: Mic | F22: 0 | K22: =SUM(F22:J22) -> 0
A23: Sam | F23: =SUM(B23:E23) -> 0 | K23: =SUM(F23:J23) -> 0
A24: Atlas Copco | B24: 53213400 | C24: 0 | D24: 0 | F24: =SUM(B24:E24) -> 53213400 | H24: 0 | I24: 11365800 | K24: =SUM(F24:J24) -> 64579200
A25: Bergen engine | F25: =SUM(B25:E25) -> 0 | K25: =SUM(F25:J25) -> 0
A26: Dometic | B26: 0 | C26: 0 | D26: 16099118 | F26: =SUM(B26:E26) -> 16099118 | G26: 0 | H26: 534016 | I26: 0 | K26: =SUM(F26:J26) -> 16633134
A27: 합 계 | B27: =SUM(B18:B26) -> 53213400 | C27: =SUM(C18:C26) -> 62857134 | D27: =SUM(D18:D26) -> 8.7464053e+08 | E27: =SUM(E18:E26) -> 9.1670839e+08 | F27: =SUM(B27:E27) -> 1.9074195e+09 | G27: =SUM(G18:G26) -> 8.5532265e+08 | H27: =SUM(H18:H26) -> 1.2298988e+08 | I27: =SUM(I18:I26) -> 11365800 | J27: =SUM(J18:J26) -> 0 | K27: =SUM(F27:J27) -> 2897097792
A29: 3월 이월 | L29: 해외영업팀
A30: 업체명 | B30: 소재비 | F30: 소재합계 | G30: 가공1 | H30: 가공2 | I30: 가공3 | J30: 기타 | K30: 합 계 | L30: 비 고
B31: 사형 | C31: 자동 | D31: 금형1 (앨리슨외) | E31: 금형2 (앨리슨)
A32: Allison | B32: =B5-B18 -> 0 | C32: =C5-C18 -> 0 | D32: =D5-D18 -> 0 | E32: =E5-E18 -> 0 | F32: =F5-F18 -> 0 | G32: =G5-G18 -> 0 | H32: =H5-H18 -> 0 | I32: =I5-I18 -> 0 | K32: =SUM(F32:J32) -> 0
A33: Mercury | B33: =B6-B19 -> 0 | C33: =C6-C19 -> 0 | D33: =D6-D19 -> 3.016082e+08 | E33: =E6-E19 -> 0 | F33: =F6-F19 -> 3.016082e+08 | G33: =G6-G19 -> 71610786 | H33: =H6-H19 -> 48405241 | I33: =I6-I19 -> 0 | K33: =SUM(F33:J33) -> 4.2162422e+08
A34: Polaris | B34: =B7-B20 -> 0 | C34: =C7-C20 -> 0 | D34: =D7-D20 -> 2.6948131e+08 | E34: =E7-E20 -> 0 | F34: =F7-F20 -> 2.6948131e+08 | G34: =G7-G20 -> 0 | H34: =H7-H20 -> 1.1478327e+08 | I34: =I7-I20 -> 0 | K34: =SUM(F34:J34) -> 3.8426458e+08
A35: Emerson | B35: =B8-B21 -> 0 | C35: =C8-C21 -> 0 | D35: =D8-D21 -> 45203106 | E35: =E8-E21 -> 0 | F35: =F8-F21 -> 45203106 | G35: =G8-G21 -> 0 | H35: =H8-H21 -> 21369007 | I35: =I8-I21 -> 5758997.2 | K35: =SUM(F35:J35) -> 72331110
A36: Mic | B36: =B9-B22 -> 100365532 | C36: =C9-C22 -> 0 | D36: =D9-D22 -> 0 | E36: =E9-E22 -> 0 | F36: =F9-F22 -> 100365532 | G36: =G9-G22 -> 0 | H36: =H9-H22 -> 0 | I36: =I9-I22 -> 29841185 | K36: =SUM(F36:J36) -> 130206717
A37: Sam | B37: =B10-B23 -> 77808900 | C37: =C10-C23 -> 0 | D37: =D10-D23 -> 0 | E37: =E10-E23 -> 0 | F37: =F10-F23 -> 77808900 | G37: =G10-G23 -> 0 | H37: =H10-H23 -> 1200000 | I37: =I10-I23 -> 930000 | K37: =SUM(F37:J37) -> 79938900
A38: Atlas Copco | B38: =B11-B24 -> 0 | C38: =C11-C24 -> 0 | D38: =D11-D24 -> 0 | E38: =E11-E24 -> 0 | F38: =F11-F24 -> 0 | G38: =G11-G24 -> 0 | H38: =H11-H24 -> 0 | I38: =I11-I24 -> 0 | K38: =SUM(F38:J38) -> 0
A39: Bergen engine | B39: =B12-B25 -> 23459331 | C39: =C12-C25 -> 41356010 | D39: =D12-D25 -> 0 | E39: =E12-E25 -> 0 | F39: =F12-F25 -> 64815341 | G39: =G12-G25 -> 0 | H39: =H12-H25 -> 6635952 | I39: =I12-I25 -> 84879381 | K39: =SUM(F39:J39) -> 156330674
A40: Dometic | B40: =B13-B26 -> 0 | C40: =C13-C26 -> 0 | D40: =D13-D26 -> 0 | E40: =E13-E26 -> 0 | F40: =F13-F26 -> 0 | G40: =G13-G26 -> 0 | H40: =H13-H26 -> 0 | I40: =I13-I26 -> 0 | K40: =SUM(F40:J40) -> 0
A41: 합 계 | B41: =SUM(B32:B40) -> 2.0163376e+08 | C41: =SUM(C32:C40) -> 41356010 | D41: =SUM(D32:D40) -> 6.1629261e+08 | E41: =SUM(E32:E40) -> 0 | F41: =SUM(B41:E41) -> 8.5928239e+08 | G41: =SUM(G32:G40) -> 71610786 | H41: =SUM(H32:H40) -> 1.9239347e+08 | I41: =SUM(I32:I40) -> 1.2140956e+08 | J41: =SUM(J32:J40) -> 0 | K41: =SUM(F41:J41) -> 1.2446962e+09
...

Sheet 환율
A1: 날짜 | B1: 환율
A2: - | B2: 0
A3: 43466 | B3: 1118.1
A4: 43467 | B4: 1118.1
A5: 43468 | B5: 1119
A6: 43469 | B6: 1127.5
A7: 43470 | B7: 1127.5
A8: 43471 | B8: 1127.5
A9: 43472 | B9: 1125.2
A10: 43473 | B10: 1118
A11: 43474 | B11: 1121.7
A12: 43475 | B12: 1121.6
A13: 43476 | B13: 1118.9
A14: 43477 | B14: 1118.9
... A625: 44088 | B625: 1188.3
A626: 44089 | B626: 1184.2 | C626: SAM | D626: 60
A627: 44090 | B627: 1180.5 | C627: EMERSON | D627: 80
A628: 44091 | B628: 1177.8 | C628: SEASTAR | D628: 60
A629: 44092 | B629: 1175.4 | C629: MC | D629: 60
A630: 44093 | B630: 1175.4 | C630: 콜라 | D630: 60
A631: 44094 | B631: 1175.4 | C631: mercury | D631: 60
A632: 44095 | B632: 1163.6 | C632: AMAT | D632: 45
A633: 44096 | B633: 1160.6 | C633: SINKO | D633: X
A634: 44097 | B634: 1163.9 | C634: R&R | D634: X
A635: 44098 | B635: 1164.4 | C635: OSHKOSH | D635: X
A636: 44099 | B636: 1170.3
A637: 44100 | B637: 1170.3
A638: 44101 | B638: 1170.3
A639: 44102 | B639: 1170.5
A640: 44103 | B640: 1173.5
A641: 44104 | B641: 1173.5
A642: 44105 | B642: 1173.5
A643: 44106 | B643: 1173.5
A644: 44107 | B644: 1173.5
A645: 44108 | B645: 1173.5
A646: 44109 | B646: 1169.5
A647: 44110 | B647: 1163.4
... A853: 44316 | B853: 1107.4
A854: 44317 | B854: 1107.4 | E854: SAM | F854: =#REF!+60 -> #REF!
A855: 44318 | B855: 1107.4 | E855: EMERSON | F855: =#REF!+60 -> #REF!
...
