Workbook

Sheet 24.01 (갑)
A2: ※ 2024년 1월 마감내역 ※
A7: 거래처 | B7: Invoice | C7: 면장번호 | D7: BL일자 | E7: 환율 | F7: 금액
F8: 외화금액 | G8: 원화환산금액 | H8: 전월금액 | I8: 증감액 | J8: 면장 | K8: Invoice | L8: B/L
A9: Allison | B9: DSM2401-AL01 | C9: 4107224500160X | D9: 45311 | E9: =VLOOKUP(D9,환율!$A$1798:$B$2033,2,) -> 1342.4 | F9: 385151.64 | G9: =ROUNDDOWN(F9*E9,0) -> 517027561 | J9: O | K9: O | L9: O
B10: DSM2401-AL02 | C10: 4107224500277X | D10: 45321 | E10: =VLOOKUP(D10,환율!$A$1798:$B$2033,2,) -> 1336.9 | F10: 402501.16 | G10: =ROUNDDOWN(F10*E10,0) -> 538103800 | J10: O | K10: O | L10: O
B11: DSM2401-AL03 | C11: 4107224500361X | D11: 45321 | E11: =VLOOKUP(D11,환율!$A$1798:$B$2033,2,) -> 1336.9 | F11: 406423.46 | G11: =ROUNDDOWN(F11*E11,0) -> 543347523 | J11: O | K11: O | L11: O
B12: DSM2401-AL04 | C12: 4107224500397X | D12: 45328 | E12: =VLOOKUP(D12,환율!$A$1798:$B$2033,2,) -> 1334.6 | F12: 199251.22 | G12: =ROUNDDOWN(F12*E12,0) -> 265920678 | J12: O | K12: O | L12: O
C13: 소계 | F13: =SUM(F9:F12) -> 1393327.5 | G13: =SUM(G9:G12) -> 1864399562 | H13: 1660278856 | I13: =+G13-H13 -> 204120706
A14: Polaris | B14: 2401P01 | C14: 4107224900077X | D14: 45312 | E14: =VLOOKUP(D14,환율!$A$1798:$B$2033,2,) -> 1342.4 | F14: 19674.63 | G14: =ROUNDDOWN(F14*E14,0) -> 26411223 | J14: O | K14: O | L14: O
B15: 2401P02 | C15: 4107224500018X | D15: 45299 | E15: =VLOOKUP(D15,환율!$A$1798:$B$2033,2,) -> 1313.7 | F15: 73041 | G15: =ROUNDDOWN(F15*E15,0) -> 95953961 | J15: O | K15: O | L15: O
B16: 2401P03 | C16: 4107224500005X | D16: 45302 | E16: =VLOOKUP(D16,환율!$A$1798:$B$2033,2,) -> 1320.1 | F16: 6482.88 | G16: =ROUNDDOWN(F16*E16,0) -> 8558049 | J16: O | K16: O | L16: O
B17: 2401P04 | C17: 4107224500122X | D17: 45310 | E17: =VLOOKUP(D17,환율!$A$1798:$B$2033,2,) -> 1342.4 | F17: 40017.78 | G17: =ROUNDDOWN(F17*E17,0) -> 53719867 | J17: O | K17: O | L17: O
B18: 2401P05 | C18: 4107224500195X | D18: 45312 | E18: =VLOOKUP(D18,환율!$A$1798:$B$2033,2,) -> 1342.4 | F18: 43.6 | G18: =ROUNDDOWN(F18*E18,0) -> 58528 | J18: O | K18: O | L18: O
B19: 2401P06 | C19: 4107224500196X | D19: 45312 | E19: =VLOOKUP(D19,환율!$A$1798:$B$2033,2,) -> 1342.4 | F19: 346.48 | G19: =ROUNDDOWN(F19*E19,0) -> 465114 | J19: O | K19: O | L19: O
B20: 2401P07 | C20: 4107224500197X | D20: 45312 | E20: =VLOOKUP(D20,환율!$A$1798:$B$2033,2,) -> 1342.4 | F20: 361.16 | G20: =ROUNDDOWN(F20*E20,0) -> 484821 | J20: O | K20: O | L20: O
B21: 2401P08 | C21: 4107224500237X | D21: 45317 | E21: =VLOOKUP(D21,환율!$A$1798:$B$2033,2,) -> 1335.7 | F21: 34925.46 | G21: =ROUNDDOWN(F21*E21,0) -> 46649936 | J21: O | K21: O | L21: O
B22: 2401P09 | C22: 4107224500306X | D22: 45321 | E22: =VLOOKUP(D22,환율!$A$1798:$B$2033,2,) -> 1336.9 | F22: 26256.96 | G22: =ROUNDDOWN(F22*E22,0) -> 35102929 | J22: O | K22: O | L22: O
B23: 2401P11 | C23: 4107224500307X | D23: 45321 | E23: =VLOOKUP(D23,환율!$A$1798:$B$2033,2,) -> 1336.9 | F23: 24685.2 | G23: =ROUNDDOWN(F23*E23,0) -> 33001643 | J23: O | K23: O | L23: O
B24: 2401P13 | C24: 4107224500308X | D24: 45321 | E24: =VLOOKUP(D24,환율!$A$1798:$B$2033,2,) -> 1336.9 | F24: 1628.64 | G24: =ROUNDDOWN(F24*E24,0) -> 2177328 | J24: O | K24: O | L24: O
B25: 2401P10 | C25: 4107224500363X | D25: 45325 | E25: =VLOOKUP(D25,환율!$A$1798:$B$2033,2,) -> 1332.5 | F25: 57911.04 | G25: =ROUNDDOWN(F25*E25,0) -> 77166460 | J25: O | K25: O | L25: O
B26: 2401P12 | C26: 4107224900220X | D26: 45327 | E26: =VLOOKUP(D26,환율!$A$1798:$B$2033,2,) -> 1325.1 | F26: 27779.76 | G26: =IFERROR(ROUNDDOWN(F26*E26,0),"") -> 36810959 | J26: O | K26: O
C27: 소계 | F27: =SUM(F14:F26) -> 313154.59 | G27: =SUM(G14:G26) -> 416560818 | H27: 331149003 | I27: =+G27-H27 -> 85411815
A28: Mercury | B28: DSM2401-01 | C28: 4107224500004X | D28: 45299 | E28: =VLOOKUP(D28,환율!$A$1798:$B$2033,2,) -> 1313.7 | F28: 63667.1 | G28: =ROUNDDOWN(F28*E28,0) -> 83639469 | J28: O | K28: O | L28: O
B29: DSM2401-02 | C29: 4107224500055X | D29: 45304 | E29: =VLOOKUP(D29,환율!$A$1798:$B$2033,2,) -> 1316 | F29: 97225.68 | G29: =ROUNDDOWN(F29*E29,0) -> 127948994 | J29: O | K29: O | L29: O
B30: DSM2401-03 | C30: 4107224500062X | D30: 45303 | E30: =VLOOKUP(D30,환율!$A$1798:$B$2033,2,) -> 1316 | F30: 119944.3 | G30: =ROUNDDOWN(F30*E30,0) -> 157846698 | J30: O | K30: O | L30: O
B31: DSM2401-04 | C31: 4107224500063X | D31: 45310 | E31: =VLOOKUP(D31,환율!$A$1798:$B$2033,2,) -> 1342.4 | F31: 26758.9 | G31: =ROUNDDOWN(F31*E31,0) -> 35921147 | J31: O | K31: O | L31: O
B32: DSM2401-05 | C32: 4107224500093X | D32: 45319 | E32: =VLOOKUP(D32,환율!$A$1798:$B$2033,2,) -> 1335.7 | F32: 3409.9 | G32: =ROUNDDOWN(F32*E32,0) -> 4554603 | J32: O | K32: O | L32: O
B33: DSM2401-06 | C33: 4107224500170X | D33: 45309 | E33: =VLOOKUP(D33,환율!$A$1798:$B$2033,2,) -> 1343.2 | F33: 112875.28 | G33: =ROUNDDOWN(F33*E33,0) -> 151614076 | J33: O | K33: O | L33: O
B34: DSM2401-07 | C34: 4107224500171X | D34: 45309 | E34: =VLOOKUP(D34,환율!$A$1798:$B$2033,2,) -> 1343.2 | F34: 7689.17 | G34: =ROUNDDOWN(F34*E34,0) -> 10328093 | J34: O | K34: O | L34: O
B35: DSM2401-08 | C35: 4107224500193X | D35: 45318 | E35: =VLOOKUP(D35,환율!$A$1798:$B$2033,2,) -> 1335.7 | F35: 79808.4 | G35: =ROUNDDOWN(F35*E35,0) -> 106600079 | J35: O | K35: O | L35: O
B36: DSM2401-09 | C36: 4107224500194X | D36: 45318 | E36: =VLOOKUP(D36,환율!$A$1798:$B$2033,2,) -> 1335.7 | F36: 76519.6 | G36: =ROUNDDOWN(F36*E36,0) -> 102207229 | J36: O | K36: O | L36: O
B37: DSM2401-10 | C37: 4107224500252X | D37: 45316 | E37: =VLOOKUP(D37,환율!$A$1798:$B$2033,2,) -> 1339.1 | F37: 121266.63 | G37: =ROUNDDOWN(F37*E37,0) -> 162388144 | J37: O | K37: O | L37: O
B38: DSM2401-11 | C38: 4107224500343X | D38: 45334 | E38: =VLOOKUP(D38,환율!$A$1798:$B$2033,2,) -> 1325.3 | F38: 63786.34 | G38: =ROUNDDOWN(F38*E38,0) -> 84536036 | J38: O | K38: O | L38: O
B39: DSM2401-12 | C39: 4107224500323X | D39: 45323 | E39: =VLOOKUP(D39,환율!$A$1798:$B$2033,2,) -> 1333.5 | F39: 5331.6 | G39: =ROUNDDOWN(F39*E39,0) -> 7109688 | J39: O | K39: O | L39: O
B40: DSM2401-13 | C40: 4107224500324X | D40: 45323 | E40: =VLOOKUP(D40,환율!$A$1798:$B$2033,2,) -> 1333.5 | F40: 99190.44 | G40: =ROUNDDOWN(F40*E40,0) -> 132270451 | J40: O | K40: O | L40: O
... B46: DSM2401-19 | C46: 4107224500425X | D46: 45343 | E46: =VLOOKUP(D46,환율!$A$1798:$B$2033,2,) -> 1337.9 | F46: 105721.14 | G46: =ROUNDDOWN(F46*E46,0) -> 141444313 | J46: O | K46: O | L46: O
C47: 소계 | F47: =SUM(F28:F46) -> 1253218.2 | G47: =SUM(G28:G46) -> 1667928419 | H47: 2445032253 | I47: =+G47-H47 -> -777103834
A48: Mercury China | B48: DSM2401-MC01 | C48: 4107224500028X | D48: 45297 | E48: =VLOOKUP(D48,환율!$A$1798:$B$2033,2,) -> 1310.2 | F48: 35599.17 | G48: =ROUNDDOWN(F48*E48,0) -> 46642032 | J48: O | K48: O | L48: O
B49: DSM2401-MC02 | C49: 4107224500123X | D49: 45304 | E49: =VLOOKUP(D49,환율!$A$1798:$B$2033,2,) -> 1316 | F49: 41768.76 | G49: =ROUNDDOWN(F49*E49,0) -> 54967688 | J49: O | K49: O | L49: O
B50: DSM2401-MC03 | C50: 4107224500234X | D50: 45313 | E50: =VLOOKUP(D50,환율!$A$1798:$B$2033,2,) -> 1336.5 | F50: 53517.24 | G50: =ROUNDDOWN(F50*E50,0) -> 71525791 | J50: O | K50: O | L50: O
...

Sheet 24.02 (갑)
A6: ※ 2024년 2월 마감내역 ※
A11: 거래처 | B11: Invoice | C11: 면장번호 | D11: BL일자 | E11: 환율 | F11: 금액
F12: 외화금액 | G12: 원화환산금액 | H12: 전월금액 | I12: 증감액 | J12: 면장 | K12: Invoice | L12: B/L
A13: Allison | B13: DSM2402-AL01 | C13: 4107224500486X | D13: 45340 | E13: =VLOOKUP(D13,환율!$A$1798:$B$2033,2,) -> 1333.2 | F13: 427795.16 | G13: =ROUNDDOWN(F13*E13,0) -> 570336507
B14: DSM2402-AL02 | C14: 4107224200041X | D14: 45349 | E14: =VLOOKUP(D14,환율!$A$1798:$B$2033,2,) -> 1331.4 | F14: 456352.9 | G14: =ROUNDDOWN(F14*E14,0) -> 607588251
B15: DSM2402-AL03 | C15: 4107224500626X | D15: 45353 | E15: =VLOOKUP(D15,환율!$A$1798:$B$2033,2,) -> 1334 | F15: 162496.4 | G15: =ROUNDDOWN(F15*E15,0) -> 216770197
B16: DSM2402-AL04 | C16: 4107224500662X | D16: 45354 | E16: =VLOOKUP(D16,환율!$A$1798:$B$2033,2,) -> 1334 | F16: 377546.7 | G16: =ROUNDDOWN(F16*E16,0) -> 503647297
C17: 소계 | F17: =SUM(F13:F16) -> 1424191.2 | G17: =SUM(G13:G16) -> 1898342252 | H17: 1864399562 | I17: =+G17-H17 -> 33942690
A18: Polaris | B18: 2402P01 | C18: 4107224500460X | D18: 45335 | E18: =VLOOKUP(D18,환율!$A$1798:$B$2033,2,) -> 1327.2 | F18: 65163.84 | G18: =ROUNDDOWN(F18*E18,0) -> 86485448
B19: 2402P02 | C19: 4107224500454X | D19: 45342 | E19: =VLOOKUP(D19,환율!$A$1798:$B$2033,2,) -> 1333.8 | F19: 8955.36 | G19: =ROUNDDOWN(F19*E19,0) -> 11944659
B20: 2402P03 | C20: 4107224500497X | D20: 45343 | E20: =VLOOKUP(D20,환율!$A$1798:$B$2033,2,) -> 1337.9 | F20: 48073.59 | G20: =ROUNDDOWN(F20*E20,0) -> 64317656
B21: 2402P04 | C21: 4107224500556X | D21: 45349 | E21: =VLOOKUP(D21,환율!$A$1798:$B$2033,2,) -> 1331.4 | F21: 55628.16 | G21: =ROUNDDOWN(F21*E21,0) -> 74063332
B22: 2402P05 | C22: 4107224500498X | D22: 45343 | E22: =VLOOKUP(D22,환율!$A$1798:$B$2033,2,) -> 1337.9 | F22: 234 | G22: =ROUNDDOWN(F22*E22,0) -> 313068
B23: 2402P06 | C23: 4107224500587X | D23: 45353 | E23: =VLOOKUP(D23,환율!$A$1798:$B$2033,2,) -> 1334 | F23: 25847.91 | G23: =ROUNDDOWN(F23*E23,0) -> 34481111
B24: 2402P07 | C24: 4107224500588X | D24: 45353 | E24: =VLOOKUP(D24,환율!$A$1798:$B$2033,2,) -> 1334 | F24: 622.5 | G24: =ROUNDDOWN(F24*E24,0) -> 830415
B25: 2402P08 | C25: 4107224500460X | D25: 45360 | E25: =VLOOKUP(D25,환율!$A$1798:$B$2033,2,) -> 1329.6 | F25: 48187.92 | G25: =ROUNDDOWN(F25*E25,0) -> 64070658
B26: 2402P09 | C26: 4107224500589X | D26: 45353 | E26: =VLOOKUP(D26,환율!$A$1798:$B$2033,2,) -> 1334 | F26: 116.78 | G26: =ROUNDDOWN(F26*E26,0) -> 155784
B27: 2402P10 | C27: 4107224500590X | D27: 45353 | E27: =VLOOKUP(D27,환율!$A$1798:$B$2033,2,) -> 1334 | F27: 828.08 | G27: =ROUNDDOWN(F27*E27,0) -> 1104658
B28: 2402P01TC | D28: 45351 | E28: =VLOOKUP(D28,환율!$A$1798:$B$2033,2,) -> 1334 | F28: 1947 | G28: =ROUNDDOWN(F28*E28,0) -> 2597298
B29: 2402P02TC | D29: 45351 | E29: =VLOOKUP(D29,환율!$A$1798:$B$2033,2,) -> 1334 | F29: 10560 | G29: =ROUNDDOWN(F29*E29,0) -> 14087040
B30: 2402P03TC | D30: 45351 | E30: =VLOOKUP(D30,환율!$A$1798:$B$2033,2,) -> 1334 | F30: 10560 | G30: =ROUNDDOWN(F30*E30,0) -> 14087040
C31: 소계 | F31: =SUM(F18:F30) -> 276725.14 | G31: =SUM(G18:G30) -> 368538167 | H31: 416560818 | I31: =+G31-H31 -> -48022651
A32: Mercury | B32: DSM2402-01 | C32: 4107224500442X | D32: 45332 | E32: =VLOOKUP(D32,환율!$A$1798:$B$2033,2,) -> 1325.3 | F32: 94449.6 | G32: =ROUNDDOWN(F32*E32,0) -> 125174054
B33: DSM2402-02 | C33: 4107224500482X | D33: 45338 | E33: =VLOOKUP(D33,환율!$A$1798:$B$2033,2,) -> 1333.2 | F33: 104611.2 | G33: =ROUNDDOWN(F33*E33,0) -> 139467651
B34: DSM2402-03 | C34: 4107224500487X | D34: 45343 | E34: =VLOOKUP(D34,환율!$A$1798:$B$2033,2,) -> 1337.9 | F34: 83955.2 | G34: =ROUNDDOWN(F34*E34,0) -> 112323662
B35: DSM2402-04 | C35: 4107224500502X | D35: 45342 | E35: =VLOOKUP(D35,환율!$A$1798:$B$2033,2,) -> 1333.8 | F35: 84099.84 | G35: =ROUNDDOWN(F35*E35,0) -> 112172366
B36: DSM2402-05 | C36: 4107224500508X | D36: 45344 | E36: =VLOOKUP(D36,환율!$A$1798:$B$2033,2,) -> 1335 | F36: 20403.08 | G36: =ROUNDDOWN(F36*E36,0) -> 27238111
B37: DSM2402-06 | C37: 4107224500539X | D37: 45349 | E37: =VLOOKUP(D37,환율!$A$1798:$B$2033,2,) -> 1331.4 | F37: 83955.2 | G37: =ROUNDDOWN(F37*E37,0) -> 111777953
B38: DSM2402-08 | C38: 4107224500517X | D38: 45342 | E38: =VLOOKUP(D38,환율!$A$1798:$B$2033,2,) -> 1333.8 | F38: 5342.4 | G38: =ROUNDDOWN(F38*E38,0) -> 7125693
B39: DSM2402-09 | C39: 4107224500586X | D39: 45349 | E39: =VLOOKUP(D39,환율!$A$1798:$B$2033,2,) -> 1331.4 | F39: 87022.22 | G39: =ROUNDDOWN(F39*E39,0) -> 115861383
B40: DSM2402-10 | C40: 4107224500518X | D40: 45342 | E40: =VLOOKUP(D40,환율!$A$1798:$B$2033,2,) -> 1333.8 | F40: 86707.6 | G40: =ROUNDDOWN(F40*E40,0) -> 115650596
B41: DSM2402-11 | C41: 4107224400086X | D41: 45337 | E41: =VLOOKUP(D41,환율!$A$1798:$B$2033,2,) -> 1336.9 | F41: 1042 | G41: =IFERROR(ROUNDDOWN(F41*E41,0),"") -> 1393049
B42: DSM2402-PS01 | C42: 4107224500491X | D42: 45330 | E42: =VLOOKUP(D42,환율!$A$1798:$B$2033,2,) -> 1325.3 | F42: 69.87 | G42: =IFERROR(ROUNDDOWN(F42*E42,0),"") -> 92598
B43: DSM2402-07 | C43: 4107224200061X | D43: 45355 | E43: =VLOOKUP(D43,환율!$A$1798:$B$2033,2,) -> 1334.1 | F43: 9516 | G43: =ROUNDDOWN(F43*E43,0) -> 12695295
B44: DSM2402-04-01 | C44: 4107224500502X | D44: 45357 | E44: =VLOOKUP(D44,환율!$A$1798:$B$2033,2,) -> 1333.2 | F44: 60489.1 | G44: =ROUNDDOWN(F44*E44,0) -> 80644068 | K44: 필요
B45: DSM2402-12 | C45: 4107224200083X | D45: 45352 | E45: =VLOOKUP(D45,환율!$A$1798:$B$2033,2,) -> 1334 | F45: 131942.84 | G45: =IFERROR(ROUNDDOWN(F45*E45,0),"") -> 176011748
B46: DSM2402-13 | C46: 4107224500628X | D46: 45359 | E46: =VLOOKUP(D46,환율!$A$1798:$B$2033,2,) -> 1329.6 | F46: 72804 | G46: =IFERROR(ROUNDDOWN(F46*E46,0),"") -> 96800198
B47: DSM2402-14 | C47: 4107224500646X | D47: 45357 | E47: =VLOOKUP(D47,환율!$A$1798:$B$2033,2,) -> 1333.2 | F47: 100359.8 | G47: =IFERROR(ROUNDDOWN(F47*E47,0),"") -> 133799685
B48: DSM2402-15 | C48: 4107224500717X | D48: 45369 | E48: =VLOOKUP(D48,환율!$A$1798:$B$2033,2,) -> 1328.4 | F48: 2786.4 | G48: =IFERROR(ROUNDDOWN(F48*E48,0),"") -> 3701453
C49: 소계 | F49: =SUM(F32:F48) -> 1029556.3 | G49: =SUM(G32:G48) -> 1371929563 | H49: 1667928419 | I49: =+G49-H49 -> -295998856
...

Sheet 24.03 (갑)
A6: ※ 2024년 3월 마감내역 ※
A11: 거래처 | B11: Invoice | C11: 면장번호 | D11: BL일자 | E11: 환율 | F11: 금액
F12: 외화금액 | G12: 원화환산금액 | H12: 전월금액 | I12: 증감액
A13: Allison | B13: DSM2403-AL01 | C13: 4107224500837X | D13: 45373 | E13: =VLOOKUP(D13,환율!$A$1798:$B$2033,2,) -> 1326.3 | F13: 371806.66 | G13: =ROUNDDOWN(F13*E13,0) -> 493127173
B14: DSM2403-AL02 | C14: 4107224500938X | D14: 45381 | E14: =VLOOKUP(D14,환율!$A$1798:$B$2033,2,) -> 1346.8 | F14: 394934.62 | G14: =ROUNDDOWN(F14*E14,0) -> 531897946
B15: DSM2403-AL03 | C15: 4107224501009X | D15: 45388 | E15: =VLOOKUP(D15,환율!$A$1798:$B$2033,2,) -> 1346.8 | F15: 469459.26 | G15: =ROUNDDOWN(F15*E15,0) -> 632267731
C16: 소계 | F16: =SUM(F13:F15) -> 1236200.5 | G16: =SUM(G13:G15) -> 1657292850 | H16: 1898342252 | I16: =+G16-H16 -> -241049402
A17: Polaris | B17: 2403P01 | C17: 4107224500910X | D17: 45382 | E17: =VLOOKUP(D17,환율!$A$1798:$B$2033,2,) -> 1346.8 | F17: 37413.84 | G17: =ROUNDDOWN(F17*E17,0) -> 50388959
B18: 2403P02 | C18: 4107224500651X | D18: 45359 | E18: =VLOOKUP(D18,환율!$A$1798:$B$2033,2,) -> 1329.6 | F18: 26809.92 | G18: =ROUNDDOWN(F18*E18,0) -> 35646469
B19: 2403P03 | C19: 4107224500652X | D19: 45359 | E19: =VLOOKUP(D19,환율!$A$1798:$B$2033,2,) -> 1329.6 | F19: 117 | G19: =ROUNDDOWN(F19*E19,0) -> 155563
B20: 2403P04 | C20: 4107224500653X | D20: 45359 | E20: =VLOOKUP(D20,환율!$A$1798:$B$2033,2,) -> 1329.6 | F20: 419.46 | G20: =ROUNDDOWN(F20*E20,0) -> 557714
B21: 2403P06 | C21: 4107224500759X | D21: 45369 | E21: =VLOOKUP(D21,환율!$A$1798:$B$2033,2,) -> 1328.4 | F21: 13014.72 | G21: =ROUNDDOWN(F21*E21,0) -> 17288754
B22: 2403P07 | C22: 4107224500857X | D22: 45376 | E22: =VLOOKUP(D22,환율!$A$1798:$B$2033,2,) -> 1336.1 | F22: 8877.6 | G22: =ROUNDDOWN(F22*E22,0) -> 11861361
B23: 2403P08 | C23: 4107224500858X | D23: 45376 | E23: =VLOOKUP(D23,환율!$A$1798:$B$2033,2,) -> 1336.1 | F23: 545.4 | G23: =ROUNDDOWN(F23*E23,0) -> 728708
B24: 2403P10 | C24: 4107224500859X | D24: 45376 | E24: =VLOOKUP(D24,환율!$A$1798:$B$2033,2,) -> 1336.1 | F24: 1092.3 | G24: =ROUNDDOWN(F24*E24,0) -> 1459422
B25: 2403P11 | C25: 4107224500860X | D25: 45376 | E25: =VLOOKUP(D25,환율!$A$1798:$B$2033,2,) -> 1336.1 | F25: 201.96 | G25: =ROUNDDOWN(F25*E25,0) -> 269838
B26: 2403P05 | C26: 4107224500975X | D26: 45395 | E26: 1349.1 | F26: 31222.8 | G26: 42122679
B27: 2403P09 | C27: 4107224501045X | D27: 45395 | E27: 1349.1 | F27: 95018.16 | G27: 128188999
B28: 2403P12 | C28: 4107224500974X | D28: 45383 | E28: =VLOOKUP(D28,환율!$A$1798:$B$2033,2,) -> 1347.4 | F28: 36154.08 | G28: =ROUNDDOWN(F28*E28,0) -> 48714007
C29: 소계 | F29: =SUM(F17:F28) -> 250887.24 | G29: =SUM(G17:G28) -> 337382473 | H29: 368538167 | I29: =+G29-H29 -> -31155694
A30: Mercury | B30: DSM2403-01 | C30: 4107224500647X | D30: 45357 | E30: =VLOOKUP(D30,환율!$A$1798:$B$2033,2,) -> 1333.2 | F30: 102904.2 | G30: =ROUNDDOWN(F30*E30,0) -> 137191879
B31: DSM2403-02 | C31: 4107224500685X | D31: 45363 | E31: =VLOOKUP(D31,환율!$A$1798:$B$2033,2,) -> 1314.4 | F31: 34203.6 | G31: =ROUNDDOWN(F31*E31,0) -> 44957211
B32: DSM2403-03 | C32: 4107224500718X | D32: 45369 | E32: =VLOOKUP(D32,환율!$A$1798:$B$2033,2,) -> 1328.4 | F32: 83243.2 | G32: =ROUNDDOWN(F32*E32,0) -> 110580266
B33: DSM2403-04 | C33: 4107224500736X | D33: 45365 | E33: =VLOOKUP(D33,환율!$A$1798:$B$2033,2,) -> 1312.8 | F33: 96886.36 | G33: =ROUNDDOWN(F33*E33,0) -> 127192413
B34: DSM2403-05 | C34: 4107224500731X | D34: 45363 | E34: =VLOOKUP(D34,환율!$A$1798:$B$2033,2,) -> 1314.4 | F34: 41102.8 | G34: =ROUNDDOWN(F34*E34,0) -> 54025520
B35: DSM2403-06 | C35: 4107224500817X | D35: 45369 | E35: =VLOOKUP(D35,환율!$A$1798:$B$2033,2,) -> 1328.4 | F35: 65799.2 | G35: =ROUNDDOWN(F35*E35,0) -> 87407657
B36: DSM2403-07 | C36: 4107224500799X | D36: 45371 | E36: =VLOOKUP(D36,환율!$A$1798:$B$2033,2,) -> 1338.5 | F36: 5342.4 | G36: =ROUNDDOWN(F36*E36,0) -> 7150802
B37: DSM2403-08 | C37: 4107224500824X | D37: 45372 | E37: =VLOOKUP(D37,환율!$A$1798:$B$2033,2,) -> 1338.7 | F37: 132347.6 | G37: =ROUNDDOWN(F37*E37,0) -> 177173732
B38: DSM2403-09 | C38: 4107224500838X | D38: 45382 | E38: =VLOOKUP(D38,환율!$A$1798:$B$2033,2,) -> 1346.8 | F38: 9352.8 | G38: =ROUNDDOWN(F38*E38,0) -> 12596351
B39: DSM2403-10 | C39: 4107224500800X | D39: 45371 | E39: =VLOOKUP(D39,환율!$A$1798:$B$2033,2,) -> 1338.5 | F39: 34203.6 | G39: =ROUNDDOWN(F39*E39,0) -> 45781518
B40: DSM2403-11 | C40: 4107224500839X | D40: 45382 | E40: =VLOOKUP(D40,환율!$A$1798:$B$2033,2,) -> 1346.8 | F40: 28916.75 | G40: =ROUNDDOWN(F40*E40,0) -> 38945078
B41: DSM2403-12 | C41: 4107224500801X | D41: 45371 | E41: =VLOOKUP(D41,환율!$A$1798:$B$2033,2,) -> 1338.5 | F41: 43245.44 | G41: =ROUNDDOWN(F41*E41,0) -> 57884021
B42: DSM2403-14 | C42: 4107224500925X | D42: 45380 | E42: =VLOOKUP(D42,환율!$A$1798:$B$2033,2,) -> 1346.8 | F42: 160274.52 | G42: =ROUNDDOWN(F42*E42,0) -> 215857723
B43: DSM2403-17 | C43: 4107224500861X | D43: 45382 | E43: =VLOOKUP(D43,환율!$A$1798:$B$2033,2,) -> 1346.8 | F43: 6100 | G43: =ROUNDDOWN(F43*E43,0) -> 8215480
B44: DSM2403-18 | C44: 4107224500937X | D44: 45373 | E44: =VLOOKUP(D44,환율!$A$1798:$B$2033,2,) -> 1326.3 | F44: 427.2 | G44: =IFERROR(ROUNDDOWN(F44*E44,0),"") -> 566595
B45: DSM2403-13 | C45: 4107224501001X | D45: 45390 | E45: =VLOOKUP(D45,환율!$A$1798:$B$2033,2,) -> 1351.8 | F45: 3096.48 | G45: =ROUNDDOWN(F45*E45,0) -> 4185821
B46: DSM2403-15 | C46: 4107224500935X | D46: 45393 | E46: =VLOOKUP(D46,환율!$A$1798:$B$2033,2,) -> 1354.4 | F46: 59556 | G46: =ROUNDDOWN(F46*E46,0) -> 80662646
B47: DSM2403-16 | C47: 4107224500936X | D47: 45384 | E47: =VLOOKUP(D47,환율!$A$1798:$B$2033,2,) -> 1347.1 | F47: 52045.2 | G47: =ROUNDDOWN(F47*E47,0) -> 70110088
B48: DSM2403-19 | C48: 4107224501002X | D48: 45390 | E48: =VLOOKUP(D48,환율!$A$1798:$B$2033,2,) -> 1351.8 | F48: 2392.32 | G48: =IFERROR(ROUNDDOWN(F48*E48,0),"") -> 3233938
B49: DSM2403-20 | C49: 4107224501003X | D49: 45390 | E49: =VLOOKUP(D49,환율!$A$1798:$B$2033,2,) -> 1351.8 | F49: 125932.8 | G49: =IFERROR(ROUNDDOWN(F49*E49,0),"") -> 170235959
...

Sheet 24.04 (갑)
A6: ※ 2024년 4월 마감내역 ※
A11: 거래처 | B11: Invoice | C11: 면장번호 | D11: 인보이스 날짜 | E11: BL일자 | F11: 환율 | G11: 금액
G12: 외화금액 | H12: 원화환산금액 | I12: 전월금액 | J12: 증감액
A13: Allison | B13: DSM2404-AL01 | C13: 4107224501090X | E13: 45394 | F13: =VLOOKUP(E13,환율!$A$1798:$B$2033,2,) -> 1363.7 | G13: 361397.27 | H13: =ROUNDDOWN(G13*F13,0) -> 492837457
B14: DSM2404-AL02 | C14: 4107224501153X | E14: 45397 | F14: =VLOOKUP(E14,환율!$A$1798:$B$2033,2,) -> 1371.6 | G14: 217128.42 | H14: =ROUNDDOWN(G14*F14,0) -> 297813340
B15: DSM2404-AL03 | C15: 4107224501251X | E15: 45407 | F15: =VLOOKUP(E15,환율!$A$1798:$B$2033,2,) -> 1370 | G15: 429544 | H15: =ROUNDDOWN(G15*F15,0) -> 588475280
B16: DSM2404-AL04 | C16: 4107224501344X | E16: 45421 | F16: =VLOOKUP(E16,환율!$A$1798:$B$2033,2,) -> 1364.4 | G16: 401730.88 | H16: =ROUNDDOWN(G16*F16,0) -> 548121612
C17: 소계 | G17: =SUM(G13:G16) -> 1409800.6 | H17: =SUM(H13:H16) -> 1927247689 | I17: 1657292850 | J17: =+H17-I17 -> 269954839
A18: Polaris | B18: 2404P01 | C18: 4107224501046X | D18: 45373 | E18: 45393 | F18: =VLOOKUP(E18,환율!$A$1798:$B$2033,2,) -> 1354.4 | G18: 39824.64 | H18: =ROUNDDOWN(G18*F18,0) -> 53938492
B19: 2404P02 | C19: 4107224501116X | D19: 45377 | E19: 45401 | F19: =VLOOKUP(E19,환율!$A$1798:$B$2033,2,) -> 1375.9 | G19: 29769.12 | H19: =ROUNDDOWN(G19*F19,0) -> 40959332
B20: 2404P03 | C20: 4107224501169X | D20: 45392 | E20: 45404 | F20: =VLOOKUP(E20,환율!$A$1798:$B$2033,2,) -> 1385 | G20: 91427.76 | H20: =ROUNDDOWN(G20*F20,0) -> 126627447
B21: 2404P04 | C21: 4107224501206X | D21: 45397 | E21: 45406 | F21: =VLOOKUP(E21,환율!$A$1798:$B$2033,2,) -> 1377.9 | G21: 12823.92 | H21: =ROUNDDOWN(G21*F21,0) -> 17670079
B22: 2404P06 | C22: 4107224501166X | D22: 45397 | E22: 45403 | F22: =VLOOKUP(E22,환율!$A$1798:$B$2033,2,) -> 1375.9 | G22: 11829.6 | H22: =ROUNDDOWN(G22*F22,0) -> 16276346
B23: 2404P08 | C23: 4107224501207X | D23: 45397 | E23: 45406 | F23: =VLOOKUP(E23,환율!$A$1798:$B$2033,2,) -> 1377.9 | G23: 173.8 | H23: =ROUNDDOWN(G23*F23,0) -> 239479
B24: 2404P01TA | E24: 45386 | F24: =VLOOKUP(E24,환율!$A$1798:$B$2033,2,) -> 1349.1 | G24: 13050 | H24: =ROUNDDOWN(G24*F24,0) -> 17605755
B25: 2404P05 | C25: 4107224200589X | D25: 45397 | E25: 45417 | F25: =VLOOKUP(E25,환율!$A$1798:$B$2033,2,) -> 1378.5 | G25: 38247.6 | H25: =ROUNDDOWN(G25*F25,0) -> 52724316
C26: 소계 | G26: =SUM(G18:G25) -> 237146.44 | H26: =SUM(H18:H25) -> 326041246 | I26: 337382473 | J26: =+H26-I26 -> -11341227
A27: Mercury | B27: DSM2404-01 | C27: 4107224501058X | D27: 45376 | E27: 45394 | F27: =VLOOKUP(E27,환율!$A$1798:$B$2033,2,) -> 1363.7 | G27: 64658.52 | H27: =ROUNDDOWN(G27*F27,0) -> 88174823
B28: DSM2404-02 | C28: 4107224501059X | D28: 45376 | E28: 45391 | F28: =VLOOKUP(E28,환율!$A$1798:$B$2033,2,) -> 1353.6 | G28: 65115.6 | H28: =ROUNDDOWN(G28*F28,0) -> 88140476
B29: DSM2404-03 | C29: 4107224501078X | D29: 45385 | E29: 45395 | F29: =VLOOKUP(E29,환율!$A$1798:$B$2033,2,) -> 1363.7 | G29: 132347.6 | H29: =ROUNDDOWN(G29*F29,0) -> 180482422
B30: DSM2404-04 | C30: 4107224501118X | D30: 45383 | E30: 45404 | F30: =VLOOKUP(E30,환율!$A$1798:$B$2033,2,) -> 1385 | G30: 34909.08 | H30: =ROUNDDOWN(G30*F30,0) -> 48349075
B31: DSM2404-05 | C31: 4107224501119X | D31: 45380 | E31: 45404 | F31: =VLOOKUP(E31,환율!$A$1798:$B$2033,2,) -> 1385 | G31: 1797.18 | H31: =ROUNDDOWN(G31*F31,0) -> 2489094
B32: DSM2404-06 | C32: 4107224501120X | D32: 45385 | E32: 45410 | F32: =VLOOKUP(E32,환율!$A$1798:$B$2033,2,) -> 1376.6 | G32: 84743.6 | H32: =ROUNDDOWN(G32*F32,0) -> 116658039
B33: DSM2404-07 | C33: 4107224501155X | D33: 45390 | E33: 45403 | F33: =VLOOKUP(E33,환율!$A$1798:$B$2033,2,) -> 1375.9 | G33: 102006.24 | H33: =ROUNDDOWN(G33*F33,0) -> 140350385
B34: DSM2404-08 | C34: 4107224501156X | D34: 45393 | E34: 45404 | F34: =VLOOKUP(E34,환율!$A$1798:$B$2033,2,) -> 1385 | G34: 47629.12 | H34: =ROUNDDOWN(G34*F34,0) -> 65966331
B35: DSM2404-09 | C35: 4107224501138X | D35: 45391 | E35: 45393 | F35: =VLOOKUP(E35,환율!$A$1798:$B$2033,2,) -> 1354.4 | G35: 2072.81 | H35: =ROUNDDOWN(G35*F35,0) -> 2807413
B36: DSM2404-11 | C36: 4107224501241X | D36: 45399 | E36: 45408 | F36: =VLOOKUP(E36,환율!$A$1798:$B$2033,2,) -> 1376.6 | G36: 122231.03 | H36: =ROUNDDOWN(G36*F36,0) -> 168263235
B37: DSM2404-20 | C37: 4107224501348X | D37: 45411 | E37: 45411 | F37: =VLOOKUP(E37,환율!$A$1798:$B$2033,2,) -> 1375.9 | G37: 2779 | H37: =ROUNDDOWN(G37*F37,0) -> 3823626
B38: DSM2404-PS01 | C38: 4107224501082X | D38: 45384 | E38: 45385 | F38: =VLOOKUP(E38,환율!$A$1798:$B$2033,2,) -> 1353 | G38: 2628 | H38: =ROUNDDOWN(G38*F38,0) -> 3555684
B39: DSM2404-PS02 | C39: 4107224501083X | D39: 45387 | E39: 45387 | F39: =VLOOKUP(E39,환율!$A$1798:$B$2033,2,) -> 1346.8 | G39: 2779 | H39: =ROUNDDOWN(G39*F39,0) -> 3742757
B40: DSM2404-PS03 | C40: 4107224501106X | D40: 45390 | E40: 45390 | F40: =VLOOKUP(E40,환율!$A$1798:$B$2033,2,) -> 1351.8 | G40: 216.28 | H40: =ROUNDDOWN(G40*F40,0) -> 292367
B41: DSM2404-01TA | D41: 45410 | E41: 45410 | F41: =VLOOKUP(E41,환율!$A$1798:$B$2033,2,) -> 1376.6 | G41: 11310 | H41: =ROUNDDOWN(G41*F41,0) -> 15569346
B42: DSM2404-10 | C42: 4107224501280X | D42: 45393 | E42: 45421 | F42: =VLOOKUP(E42,환율!$A$1798:$B$2033,2,) -> 1364.4 | G42: 59963.6 | H42: =ROUNDDOWN(G42*F42,0) -> 81814335
B43: DSM2404-12 | C43: 4107224501294X | D43: 45400 | E43: 45417 | F43: =VLOOKUP(E43,환율!$A$1798:$B$2033,2,) -> 1378.5 | G43: 30694.72 | H43: =ROUNDDOWN(G43*F43,0) -> 42312671
B44: DSM2404-13 | C44: 4107224501267X | D44: 45400 | E44: 45415 | F44: =VLOOKUP(E44,환율!$A$1798:$B$2033,2,) -> 1378.5 | G44: 83455.6 | H44: =ROUNDDOWN(G44*F44,0) -> 115043544
B45: DSM2404-14 | C45: 4107224501308X | D45: 45406 | E45: 45419 | F45: =VLOOKUP(E45,환율!$A$1798:$B$2033,2,) -> 1365.2 | G45: 114591.12 | H45: =ROUNDDOWN(G45*F45,0) -> 156439797
B46: DSM2404-15 | C46: 4107224501309X | D46: 45406 | E46: 45418 | F46: =VLOOKUP(E46,환율!$A$1798:$B$2033,2,) -> 1378.5 | G46: 44041.2 | H46: =ROUNDDOWN(G46*F46,0) -> 60710794
B47: DSM2404-16 | C47: 4107224501338X | D47: 45407 | E47: 45433 | F47: =VLOOKUP(E47,환율!$A$1798:$B$2033,2,) -> 1356.2 | G47: 59963.6 | H47: =ROUNDDOWN(G47*F47,0) -> 81322634
B48: DSM2404-17 | C48: 4107224501339X | D48: 45407 | E48: 45433 | F48: =VLOOKUP(E48,환율!$A$1798:$B$2033,2,) -> 1356.2 | G48: 5572.8 | H48: =ROUNDDOWN(G48*F48,0) -> 7557831
B49: DSM2404-18 | C49: 4107224501369X | D49: 45412 | E49: 45426 | F49: =VLOOKUP(E49,환율!$A$1798:$B$2033,2,) -> 1370.1 | G49: 13660.8 | H49: =ROUNDDOWN(G49*F49,0) -> 18716662
...

Sheet 24.05 (갑)
A6: ※ 2024년 5월 마감내역 ※
A11: 거래처 | B11: Invoice | C11: 면장번호 | D11: 인보이스 날짜 | E11: BL일자 | F11: 환율 | G11: 금액
G12: 외화금액 | H12: 원화환산금액 | I12: 전월금액 | J12: 증감액
A13: Allison | B13: DSM2405-AL01 | C13: 4107224501448X | D13: 45422 | E13: 45429 | F13: =VLOOKUP(E13,환율!$A$1798:$B$2033,2,) -> 1349.4 | G13: 369838.12 | H13: =ROUNDDOWN(G13*F13,0) -> 499059559 | K13: ='24.04 (갑)'!G16 -> 401730.88
B14: DSM2405-AL03 | C14: 4107224501590X | D14: 45436 | E14: 45446 | F14: =VLOOKUP(E14,환율!$A$1798:$B$2033,2,) -> 1381.6 | G14: 393378.62 | H14: =ROUNDDOWN(G14*F14,0) -> 543491901
B15: DSM2405-AL02 | C15: 4107224501665X | D15: 45443 | E15: 45449 | F15: =VLOOKUP(E15,환율!$A$1798:$B$2033,2,) -> 1373.1 | G15: 421200.02 | H15: =ROUNDDOWN(G15*F15,0) -> 578349747
A16: 소계 | G16: =SUM(G13:G15) -> 1184416.8 | H16: =SUM(H13:H15) -> 1620901207 | I16: 1927247689 | J16: =+H16-I16 -> -306346482
A17: Polaris | B17: 2405P01 | C17: 4107224501496X | D17: 45420 | E17: 45436 | F17: =VLOOKUP(E17,환율!$A$1798:$B$2033,2,) -> 1364.5 | G17: 58875.72 | H17: =ROUNDDOWN(G17*F17,0) -> 80335919
B18: 2405P02 | C18: 4107224501341X | D18: 45404 | E18: 45422 | F18: =VLOOKUP(E18,환율!$A$1798:$B$2033,2,) -> 1367.9 | G18: 36646.38 | H18: =ROUNDDOWN(G18*F18,0) -> 50128583
B19: 2405P08 | C19: 4107224501426X | D19: 45427 | E19: 45429 | F19: =VLOOKUP(E19,환율!$A$1798:$B$2033,2,) -> 1349.4 | G19: 17982.72 | H19: =ROUNDDOWN(G19*F19,0) -> 24265882
B20: 2405TC01 | E20: 45427 | F20: =VLOOKUP(E20,환율!$A$1798:$B$2033,2,) -> 1370.1 | G20: 8700 | H20: =ROUNDDOWN(G20*F20,0) -> 11919870
B21: 2405P03 | C21: 4107224501528X | D21: 45413 | E21: 45446 | F21: =VLOOKUP(E21,환율!$A$1798:$B$2033,2,) -> 1381.6 | G21: 311.35 | H21: =ROUNDDOWN(G21*F21,0) -> 430161
B22: 2405P04 | C22: 4107224501529X | D22: 45413 | E22: 45446 | F22: =VLOOKUP(E22,환율!$A$1798:$B$2033,2,) -> 1381.6 | G22: 1418.42 | H22: =ROUNDDOWN(G22*F22,0) -> 1959689
B23: 2405P05 | C23: 4107224501530X | D23: 45413 | E23: 45446 | F23: =VLOOKUP(E23,환율!$A$1798:$B$2033,2,) -> 1381.6 | G23: 780.48 | H23: =ROUNDDOWN(G23*F23,0) -> 1078311
B24: 2405P06 | C24: 4107224501531X | D24: 45413 | E24: 45446 | F24: =VLOOKUP(E24,환율!$A$1798:$B$2033,2,) -> 1381.6 | G24: 280.5 | H24: =ROUNDDOWN(G24*F24,0) -> 387538
B25: 2405P07 | C25: 4107224501645X | D25: 45432 | E25: 45455 | F25: =VLOOKUP(E25,환율!$A$1798:$B$2033,2,) -> 1377.4 | G25: 72188.46 | H25: =ROUNDDOWN(G25*F25,0) -> 99432384
B26: 2405P09 | C26: 4107224501532X | D26: 45422 | E26: 45446 | F26: =VLOOKUP(E26,환율!$A$1798:$B$2033,2,) -> 1381.6 | G26: 59702.4 | H26: =ROUNDDOWN(G26*F26,0) -> 82484835
B27: 2405P10 | C27: 4107224501623X | D27: 45424 | E27: 45446 | F27: =VLOOKUP(E27,환율!$A$1798:$B$2033,2,) -> 1381.6 | G27: 23455.2 | H27: =ROUNDDOWN(G27*F27,0) -> 32405704
B28: 2405P11 | C28: 4107224200834X | D28: 45432 | E28: 45445 | F28: =VLOOKUP(E28,환율!$A$1798:$B$2033,2,) -> 1376.5 | G28: 7153.92 | H28: =ROUNDDOWN(G28*F28,0) -> 9847370
A29: 소계 | G29: =SUM(G17:G28) -> 287495.55 | H29: =SUM(H17:H28) -> 394676246 | I29: 326041246 | J29: =+H29-I29 -> 68635000
A30: Mercury | B30: DSM2405-01 | C30: 4107224501370X | D30: 45412 | E30: 45426 | F30: =VLOOKUP(E30,환율!$A$1798:$B$2033,2,) -> 1370.1 | G30: 41977.6 | H30: =ROUNDDOWN(G30*F30,0) -> 57513509
B31: DSM2405-02 | C31: 4107224501441X | D31: 45412 | E31: 45432 | F31: =VLOOKUP(E31,환율!$A$1798:$B$2033,2,) -> 1355.2 | G31: 87484.8 | H31: =ROUNDDOWN(G31*F31,0) -> 118559400
B32: DSM2405-03 | C32: 4107224501452X | D32: 45415 | E32: 45436 | F32: =VLOOKUP(E32,환율!$A$1798:$B$2033,2,) -> 1364.5 | G32: 117941.6 | H32: =ROUNDDOWN(G32*F32,0) -> 160931313
B33: DSM2405-04 | C33: 4107224501453X | D33: 45415 | E33: 45441 | F33: =VLOOKUP(E33,환율!$A$1798:$B$2033,2,) -> 1359.5 | G33: 51112.8 | H33: =ROUNDDOWN(G33*F33,0) -> 69487851
B34: DSM2405-05 | C34: 4107224501454X | D34: 45420 | E34: 45432 | F34: =VLOOKUP(E34,환율!$A$1798:$B$2033,2,) -> 1355.2 | G34: 2779 | H34: =ROUNDDOWN(G34*F34,0) -> 3766100
B35: DSM2405-06 | C35: 4107224501425X | D35: 45420 | E35: 45421 | F35: =VLOOKUP(E35,환율!$A$1798:$B$2033,2,) -> 1364.4 | G35: 2779 | H35: =ROUNDDOWN(G35*F35,0) -> 3791667
B36: DSM2405-07 | C36: 4107224501546X | D36: 45422 | E36: 45441 | F36: =VLOOKUP(E36,환율!$A$1798:$B$2033,2,) -> 1359.5 | G36: 43746 | H36: =ROUNDDOWN(G36*F36,0) -> 59472687
B37: DSM2405-08 | C37: 4107224501500X | D37: 45422 | E37: 45438 | F37: =VLOOKUP(E37,환율!$A$1798:$B$2033,2,) -> 1364.5 | G37: 99696.8 | H37: =ROUNDDOWN(G37*F37,0) -> 136036283
B38: DSM2405-09 | C38: 4107224501489X | D38: 45422 | E38: 45429 | F38: =VLOOKUP(E38,환율!$A$1798:$B$2033,2,) -> 1349.4 | G38: 961.56 | H38: =ROUNDDOWN(G38*F38,0) -> 1297529
B39: DSM2405-10 | C39: 4107224501570X | D39: 45426 | E39: 45442 | F39: =VLOOKUP(E39,환율!$A$1798:$B$2033,2,) -> 1364.8 | G39: 23492 | H39: =ROUNDDOWN(G39*F39,0) -> 32061881
B40: DSM2405-14 | C40: 4107224501541X | D40: 45429 | E40: 45433 | F40: =VLOOKUP(E40,환율!$A$1798:$B$2033,2,) -> 1356.2 | G40: 6947.5 | H40: =ROUNDDOWN(G40*F40,0) -> 9422199
B41: DSM2405-17 | C41: 4107224501589X | D41: 45435 | E41: 45437 | F41: =VLOOKUP(E41,환율!$A$1798:$B$2033,2,) -> 1364.5 | G41: 6447.28 | H41: =ROUNDDOWN(G41*F41,0) -> 8797313
B42: DSM2405-11 | C42: 4107224501587X | D42: 45432 | E42: 45445 | F42: =VLOOKUP(E42,환율!$A$1798:$B$2033,2,) -> 1376.5 | G42: 112598.5 | H42: =ROUNDDOWN(G42*F42,0) -> 154991835 | K42: 45473
B43: DSM2405-12 | C43: 4107224501605X | D43: 45434 | E43: 45446 | F43: =VLOOKUP(E43,환율!$A$1798:$B$2033,2,) -> 1381.6 | G43: 11795 | H43: =ROUNDDOWN(G43*F43,0) -> 16295972
B44: DSM2405-13 | C44: 4107224501588X | D44: 45434 | E44: 45445 | F44: =VLOOKUP(E44,환율!$A$1798:$B$2033,2,) -> 1376.5 | G44: 6677.5 | H44: =ROUNDDOWN(G44*F44,0) -> 9191578
B45: DSM2405-15 | C45: 4107224501608X | D45: 45434 | E45: 45446 | F45: =VLOOKUP(E45,환율!$A$1798:$B$2033,2,) -> 1381.6 | G45: 5172.1 | H45: =ROUNDDOWN(G45*F45,0) -> 7145773
B46: DSM2405-16 | C46: 4107224501644X | D46: 45434 | E46: 45450 | F46: =VLOOKUP(E46,환율!$A$1798:$B$2033,2,) -> 1371.5 | G46: 98401.4 | H46: =ROUNDDOWN(G46*F46,0) -> 134957520
B47: DSM2405-18 | C47: 4107224501709X | D47: 45440 | E47: 45457 | F47: =VLOOKUP(E47,환율!$A$1798:$B$2033,2,) -> 1371 | G47: 33034.4 | H47: =ROUNDDOWN(G47*F47,0) -> 45290162
B48: DSM2405-19 | C48: 4107224501662X | D48: 45435 | E48: 45451 | F48: =VLOOKUP(E48,환율!$A$1798:$B$2033,2,) -> 1371.5 | G48: 94449.6 | H48: =ROUNDDOWN(G48*F48,0) -> 129537626
B49: DSM2405-20 | C49: 4107224501663X | D49: 45432 | E49: 45451 | F49: =VLOOKUP(E49,환율!$A$1798:$B$2033,2,) -> 1371.5 | G49: 3962.5 | H49: =ROUNDDOWN(G49*F49,0) -> 5434568
...

Sheet 24.06 (갑)
A6: ※ 2024년 6월 마감내역 ※
A11: 거래처 | B11: Invoice | C11: 면장번호 | D11: 인보이스 날짜 | E11: BL일자 | F11: 환율 | G11: 금액
G12: 외화금액 | H12: 원화환산금액 | I12: 전월금액 | J12: 증감액
A13: Allison | B13: DSM2406-AL01 | C13: 4107224501788X | D13: 45457 | E13: 45471 | F13: =VLOOKUP(E13,환율!$A$1798:$B$2033,2,) -> 1389.2 | G13: 387693.5 | H13: =ROUNDDOWN(G13*F13,0) -> 538583810
B14: DSM2406-AL02 | C14: 4107224501863X | D14: 45464 | E14: 45472 | F14: =VLOOKUP(E14,환율!$A$1798:$B$2033,2,) -> 1389.2 | G14: 393275.94 | H14: =ROUNDDOWN(G14*F14,0) -> 546338935
B15: DSM2406-AL03 | C15: 4107224501942X | D15: 45471 | E15: 45481 | F15: =VLOOKUP(E15,환율!$A$1798:$B$2033,2,) -> 1379 | G15: 273512.02 | H15: =ROUNDDOWN(G15*F15,0) -> 377173075
C16: 소계 | G16: =SUM(G13:G15) -> 1054481.5 | H16: =SUM(H13:H15) -> 1462095820 | I16: 1624481407 | J16: =+H16-I16 -> -162385587
A17: Polaris | B17: 2406P01 | C17: 4107224501683X | D17: 45439 | E17: 45459 | F17: =VLOOKUP(E17,환율!$A$1798:$B$2033,2,) -> 1371 | G17: 569.41 | H17: =ROUNDDOWN(G17*F17,0) -> 780661
B18: 2406P02 | C18: 4107224501684X | D18: 45440 | E18: 45459 | F18: =VLOOKUP(E18,환율!$A$1798:$B$2033,2,) -> 1371 | G18: 84123.36 | H18: =ROUNDDOWN(G18*F18,0) -> 115333126
B19: 2406P03 | C19: 4107224501685X | D19: 45440 | E19: 45459 | F19: =VLOOKUP(E19,환율!$A$1798:$B$2033,2,) -> 1371 | G19: 286 | H19: =ROUNDDOWN(G19*F19,0) -> 392106
B20: 2406P04 | C20: 4107224501686X | D20: 45436 | E20: 45459 | F20: =VLOOKUP(E20,환율!$A$1798:$B$2033,2,) -> 1371 | G20: 12926.4 | H20: =ROUNDDOWN(G20*F20,0) -> 17722094
B21: 2406P05 | C21: 4107224501770X | D21: 45444 | E21: 45466 | F21: =VLOOKUP(E21,환율!$A$1798:$B$2033,2,) -> 1383.8 | G21: 22986 | H21: =ROUNDDOWN(G21*F21,0) -> 31808026
B22: 2406P06 | C22: 4107224501835X | D22: 45448 | E22: 45472 | F22: =VLOOKUP(E22,환율!$A$1798:$B$2033,2,) -> 1389.2 | G22: 64059.84 | H22: =ROUNDDOWN(G22*F22,0) -> 88991929
B23: 2406P07 | C23: 4107224501836X | D23: 45450 | E23: 45472 | F23: =VLOOKUP(E23,환율!$A$1798:$B$2033,2,) -> 1389.2 | G23: 277.1 | H23: =ROUNDDOWN(G23*F23,0) -> 384947
B24: 2406P08 | C24: 4107224501790X | D24: 45397 | E24: 45467 | F24: =VLOOKUP(E24,환율!$A$1798:$B$2033,2,) -> 1389.1 | G24: 12389.76 | H24: =ROUNDDOWN(G24*F24,0) -> 17210615
B25: 2406P12 | C25: 4107224501901X | D25: 45462 | E25: 45472 | F25: =VLOOKUP(E25,환율!$A$1798:$B$2033,2,) -> 1389.2 | G25: 8308.8 | H25: =ROUNDDOWN(G25*F25,0) -> 11542584
B26: 2406P09 | C26: 4107224501898X | D26: 45455 | E26: 45475 | F26: =VLOOKUP(E26,환율!$A$1798:$B$2033,2,) -> 1380.8 | G26: 28584 | H26: =ROUNDDOWN(G26*F26,0) -> 39468787
B27: 2406P10 | C27: 4107224501900X | D27: 45457 | E27: 45475 | F27: =VLOOKUP(E27,환율!$A$1798:$B$2033,2,) -> 1380.8 | G27: 84447.18 | H27: =ROUNDDOWN(G27*F27,0) -> 116604666
C28: 소계 | G28: =SUM(G17:G27) -> 318957.85 | H28: =SUM(H17:H27) -> 440239541 | I28: 394365836 | J28: =+H28-I28 -> 45873705
A29: Mercury | B29: DSM2406-01 | C29: 4107224200946X | D29: 45442 | E29: 45460 | F29: =VLOOKUP(E29,환율!$A$1798:$B$2033,2,) -> 1377.7 | G29: 108899.2 | H29: =ROUNDDOWN(G29*F29,0) -> 150030427
B30: DSM2406-02 | C30: 4107224501721X | D30: 45442 | E30: 45466 | F30: =VLOOKUP(E30,환율!$A$1798:$B$2033,2,) -> 1383.8 | G30: 23492 | H30: =ROUNDDOWN(G30*F30,0) -> 32508229
B31: DSM2406-03 | C31: 4107224501723X | D31: 45442 | E31: 45466 | F31: =VLOOKUP(E31,환율!$A$1798:$B$2033,2,) -> 1383.8 | G31: 14770.3 | H31: =ROUNDDOWN(G31*F31,0) -> 20439141
B32: DSM2406-04 | C32: 4107224501757X | D32: 45448 | E32: 45466 | F32: =VLOOKUP(E32,환율!$A$1798:$B$2033,2,) -> 1383.8 | G32: 40676.72 | H32: =ROUNDDOWN(G32*F32,0) -> 56288445
B33: DSM2406-05 | C33: 4107224501793X | D33: 45448 | E33: 45466 | F33: =VLOOKUP(E33,환율!$A$1798:$B$2033,2,) -> 1383.8 | G33: 110200 | H33: =ROUNDDOWN(G33*F33,0) -> 152494760
B34: DSM2406-06 | C34: 4107224501809X | D34: 45448 | E34: 45471 | F34: =VLOOKUP(E34,환율!$A$1798:$B$2033,2,) -> 1389.2 | G34: 65490.88 | H34: =ROUNDDOWN(G34*F34,0) -> 90979930
B35: DSM2406-07 | C35: 4107224501855X | D35: 45457 | E35: 45471 | F35: =VLOOKUP(E35,환율!$A$1798:$B$2033,2,) -> 1389.2 | G35: 93157.6 | H35: =ROUNDDOWN(G35*F35,0) -> 129414537
B36: DSM2406-08 | C36: 4107224501869X | D36: 45457 | E36: 45477 | F36: =VLOOKUP(E36,환율!$A$1798:$B$2033,2,) -> 1389.4 | G36: 69916 | H36: =ROUNDDOWN(G36*F36,0) -> 97141290
B37: DSM2406-09 | C37: 4107224501870X | D37: 45459 | E37: 45476 | F37: =VLOOKUP(E37,환율!$A$1798:$B$2033,2,) -> 1387.4 | G37: 2282.4 | H37: =ROUNDDOWN(G37*F37,0) -> 3166601
B38: DSM2406-10 | C38: 4107224501966X | D38: 45467 | E38: 45479 | F38: =VLOOKUP(E38,환율!$A$1798:$B$2033,2,) -> 1381.9 | G38: 94449.6 | H38: =ROUNDDOWN(G38*F38,0) -> 130519902
B39: DSM2406-11 | C39: 4107224501977X | D39: 45467 | E39: 45487 | F39: =VLOOKUP(E39,환율!$A$1798:$B$2033,2,) -> 1380.1 | G39: 23607.71 | H39: =ROUNDDOWN(G39*F39,0) -> 32581000
B40: DSM2406-12 | C40: 4107224501978X | D40: 45469 | E40: 45483 | F40: =VLOOKUP(E40,환율!$A$1798:$B$2033,2,) -> 1383.4 | G40: 23025.52 | H40: =ROUNDDOWN(G40*F40,0) -> 31853504
C41: 소계 | G41: =SUM(G29:G40) -> 669967.93 | H41: =SUM(H29:H40) -> 927417766 | I41: 1251716894 | J41: =+H41-I41 -> -324299128
A42: Mercury China | B42: DSM2406-MC01 | C42: 4107224501606X | D42: 45439 | E42: 45444 | F42: =VLOOKUP(E42,환율!$A$1798:$B$2033,2,) -> 1376.5 | G42: 112025.52 | H42: =ROUNDDOWN(G42*F42,0) -> 154203128
B43: DSM2406-MC02 | C43: 4107224501714X | D43: 45447 | E43: 45451 | F43: =VLOOKUP(E43,환율!$A$1798:$B$2033,2,) -> 1371.5 | G43: 60685.2 | H43: =ROUNDDOWN(G43*F43,0) -> 83229751
B44: DSM2406-MC03 | C44: 4107224501810X | D44: 45459 | E44: 45464 | F44: =VLOOKUP(E44,환율!$A$1798:$B$2033,2,) -> 1383.8 | G44: 128835.89 | H44: =ROUNDDOWN(G44*F44,0) -> 178283104
C45: 소계 | G45: =SUM(G42:G44) -> 301546.61 | H45: =SUM(H42:H44) -> 415715983 | I45: 220322899 | J45: =+H45-I45 -> 195393084
A46: R&R | B46: DSM2406-R01 | C46: 4107224502176X | D46: 45464 | E46: 45500 | F46: 1385.4 | G46: =H46/F46 -> 57694.714 | H46: 79930257
C47: 소계 | G47: =SUM(G46:G46) -> 57694.714 | H47: =SUM(H46:H46) -> 79930257 | I47: 27644528 | J47: =+H47-I47 -> 52285729
A48: SAM | B48: DSM2406-SM01 | C48: 4112924060150X | D48: 45459 | E48: 45471 | F48: =VLOOKUP(E48,환율!$A$1798:$B$2033,2,) -> 1389.2 | G48: 39476 | H48: =ROUNDDOWN(G48*F48,0) -> 54840059
C49: 소계 | G49: =SUM(G48:G48) -> 39476 | H49: =SUM(H48:H48) -> 54840059 | I49: 113368755 | J49: =+H49-I49 -> -58528696
...

Sheet 24.07 (갑) 
A6: ※ 2024년 7월 마감내역 ※
A11: 거래처 | B11: Invoice | C11: 면장번호 | D11: 인보이스 날짜 | E11: BL일자 | F11: 환율 | G11: 금액
G12: 외화금액 | H12: 원화환산금액 | I12: 전월금액 | J12: 증감액
A13: Allison | B13: DSM2407-AL01 | C13: 4107224502110X | E13: 45493 | F13: =VLOOKUP(E13,환율!$A$1798:$B$2033,2,) -> 1379.9 | G13: 384460.73 | H13: =ROUNDDOWN(G13*F13,0) -> 530517361
B14: DSM2407-AL02 | C14: 4107224502212X | E14: 45501 | F14: =VLOOKUP(E14,환율!$A$1798:$B$2194,2,) -> 1385.4 | G14: 385470.94 | H14: =ROUNDDOWN(G14*F14,0) -> 534031440
A15: 소계 | G15: =SUM(G13:G14) -> 769931.67 | H15: =SUM(H13:H14) -> 1064548801 | I15: 1462095820 | J15: =+H15-I15 -> -397547019
A16: Polaris | B16: 2407P01 | C16: 4107224502036X | E16: 45491 | F16: =VLOOKUP(E16,환율!$A$1798:$B$2194,2,) -> 1381.5 | G16: 62353.44 | H16: =ROUNDDOWN(G16*F16,0) -> 86141277
B17: 2407P02 | C17: 4107224201235X | E17: 45488 | F17: =VLOOKUP(E17,환율!$A$1798:$B$2194,2,) -> 1376.3 | G17: 28177.92 | H17: =ROUNDDOWN(G17*F17,0) -> 38781271
B18: 2407P03 | C18: 4107224502037X | E18: 45491 | F18: =VLOOKUP(E18,환율!$A$1798:$B$2194,2,) -> 1381.5 | G18: 400.17 | H18: =ROUNDDOWN(G18*F18,0) -> 552834
B19: 2407P04 | C19: 4107224502038X | E19: 45491 | F19: =VLOOKUP(E19,환율!$A$1798:$B$2194,2,) -> 1381.5 | G19: 845.7 | H19: =ROUNDDOWN(G19*F19,0) -> 1168334
B20: 2407P05 | C20: 4107224502039X | E20: 45491 | F20: =VLOOKUP(E20,환율!$A$1798:$B$2194,2,) -> 1381.5 | G20: 516.4 | H20: =ROUNDDOWN(G20*F20,0) -> 713406
B21: 2407P07 | C21: 4107224502194X | E21: 45502 | F21: =VLOOKUP(E21,환율!$A$1798:$B$2194,2,) -> 1385.4 | G21: 53265.6 | H21: =ROUNDDOWN(G21*F21,0) -> 73794162
B22: 2407P09 | C22: 4107224502177X | E22: 45503 | F22: =VLOOKUP(E22,환율!$A$1798:$B$2194,2,) -> 1382 | G22: 1423.94 | H22: =ROUNDDOWN(G22*F22,0) -> 1967885
B23: 2407P06 | C23: 4107224502284X | E23: 45517 | F23: =VLOOKUP(E23,환율!$A$1798:$B$2194,2,) -> 1367.7 | G23: 18914.4 | H23: =ROUNDDOWN(G23*F23,0) -> 25869224
B24: 2407P08 | C24: 4107224502134X | E24: 45507 | F24: =VLOOKUP(E24,환율!$A$1798:$B$2194,2,) -> 1365.9 | G24: 9430.56 | H24: =ROUNDDOWN(G24*F24,0) -> 12881201
B25: 2407P01TC | E25: 45485 | F25: =VLOOKUP(E25,환율!$A$1798:$B$2194,2,) -> 1380.1 | G25: 2006 | H25: =ROUNDDOWN(G25*F25,0) -> 2768480
B26: 2407P02TC | E26: 45475 | F26: =VLOOKUP(E26,환율!$A$1798:$B$2194,2,) -> 1380.8 | G26: 10880 | H26: =ROUNDDOWN(G26*F26,0) -> 15023104
B27: 2407P03TC | E27: 45475 | F27: =VLOOKUP(E27,환율!$A$1798:$B$2194,2,) -> 1380.8 | G27: 10880 | H27: =ROUNDDOWN(G27*F27,0) -> 15023104
B28: 2407P139TA | E28: 45490 | F28: =VLOOKUP(E28,환율!$A$1798:$B$2194,2,) -> 1386 | G28: 9867 | H28: =ROUNDDOWN(G28*F28,0) -> 13675662
B29: 2407P140TA | E29: 45490 | F29: =VLOOKUP(E29,환율!$A$1798:$B$2194,2,) -> 1386 | G29: 9867 | H29: =ROUNDDOWN(G29*F29,0) -> 13675662
B30: 2407P436TA | E30: 45490 | F30: =VLOOKUP(E30,환율!$A$1798:$B$2194,2,) -> 1386 | G30: 10890 | H30: =ROUNDDOWN(G30*F30,0) -> 15093540
B31: 2407P563TA | E31: 45490 | F31: =VLOOKUP(E31,환율!$A$1798:$B$2194,2,) -> 1386 | G31: 8728.5 | H31: =ROUNDDOWN(G31*F31,0) -> 12097701
A32: 소계 | G32: =SUM(G16:G31) -> 238446.63 | H32: =SUM(H16:H31) -> 329226847 | I32: 440239541 | J32: =+H32-I32 -> -111012694
A33: Mercury | B33: DSM2407-01 | C33: 4107224502006X | E33: 45501 | F33: 1385.4 | G33: 7164.2 | H33: =ROUNDDOWN(G33*F33,0) -> 9925282
B34: DSM2407-02 | C34: 4107224502007X | E34: 45486 | F34: =VLOOKUP(E34,환율!$A$1798:$B$2033,2,) -> 1380.1 | G34: 100924.67 | H34: =ROUNDDOWN(G34*F34,0) -> 139286137
B35: DSM2407-03 | C35: 4107224201215X | E35: 45483 | F35: =VLOOKUP(E35,환율!$A$1798:$B$2033,2,) -> 1383.4 | G35: 69532.04 | H35: =ROUNDDOWN(G35*F35,0) -> 96190624
B36: DSM2407-04 | C36: 4107224502000X | E36: 45478 | F36: =VLOOKUP(E36,환율!$A$1798:$B$2033,2,) -> 1381.9 | G36: 1629.36 | H36: =ROUNDDOWN(G36*F36,0) -> 2251612
B37: DSM2407-05 | C37: 4107224501989X | E37: 45476 | F37: =VLOOKUP(E37,환율!$A$1798:$B$2033,2,) -> 1387.4 | G37: 190.2 | H37: =ROUNDDOWN(G37*F37,0) -> 263883
B38: DSM2407-06 | C38: 4107224502008X | E38: 45501 | F38: =VLOOKUP(E38,환율!$A$1798:$B$2194,2,) -> 1385.4 | G38: 3216.96 | H38: =ROUNDDOWN(G38*F38,0) -> 4456776
B39: DSM2407-07 | C39: 4107224502009X | E39: 45493 | F39: =VLOOKUP(E39,환율!$A$1798:$B$2194,2,) -> 1379.9 | G39: 5040 | H39: =ROUNDDOWN(G39*F39,0) -> 6954696
B40: DSM2407-08 | C40: 4107224502113X | E40: 45493 | F40: =VLOOKUP(E40,환율!$A$1798:$B$2194,2,) -> 1379.9 | G40: 106314.36 | H40: =ROUNDDOWN(G40*F40,0) -> 146703185
B41: DSM2407-09 | C41: 4107224502114X | E41: 45498 | F41: =VLOOKUP(E41,환율!$A$1798:$B$2194,2,) -> 1385.1 | G41: 45949.6 | H41: =ROUNDDOWN(G41*F41,0) -> 63644790
B42: DSM2407-11 | C42: 4107224502178X | E42: 45499 | F42: =VLOOKUP(E42,환율!$A$1798:$B$2194,2,) -> 1385.4 | G42: 52511.9 | H42: =ROUNDDOWN(G42*F42,0) -> 72749986
B43: DSM2407-PS01 | C43: 4107224201221X | E43: 45479 | F43: =VLOOKUP(E43,환율!$A$1798:$B$2194,2,) -> 1381.9 | G43: 914.02 | H43: =ROUNDDOWN(G43*F43,0) -> 1263084
B44: DSM2407-10 | C44: 4107224502073X | E44: 45506 | F44: =VLOOKUP(E44,환율!$A$1798:$B$2194,2,) -> 1365.9 | G44: 7930 | H44: =ROUNDDOWN(G44*F44,0) -> 10831587
B45: DSM2407-12 | C45: 4107224502179X | E45: 45506 | F45: =VLOOKUP(E45,환율!$A$1798:$B$2194,2,) -> 1365.9 | G45: 45949.6 | H45: =ROUNDDOWN(G45*F45,0) -> 62762558
B46: DSM2407-13 | C46: 4107224502237X | E46: 45509 | F46: =VLOOKUP(E46,환율!$A$1798:$B$2194,2,) -> 1372.8 | G46: 78708 | H46: =ROUNDDOWN(G46*F46,0) -> 108050342
B47: DSM2407-14 | C47: 4107224502238X | E47: 45512 | F47: =VLOOKUP(E47,환율!$A$1798:$B$2194,2,) -> 1376.4 | G47: 11746 | H47: =ROUNDDOWN(G47*F47,0) -> 16167194
B48: DSM2407-15 | C48: 4107224502234X | E48: 45506 | F48: =VLOOKUP(E48,환율!$A$1798:$B$2194,2,) -> 1365.9 | G48: 8540 | H48: =ROUNDDOWN(G48*F48,0) -> 11664786
B49: DSM2407-01TA | E49: 45482 | F49: =VLOOKUP(E49,환율!$A$1798:$B$2194,2,) -> 1379.4 | G49: 82800 | H49: =ROUNDDOWN(G49*F49,0) -> 114214320
...

Sheet 24.08 (갑) 
A6: ※ 2024년 8월 마감내역 ※
A11: 거래처 | B11: Invoice | C11: 면장번호 | D11: 인보이스 날짜 | E11: BL일자 | F11: 환율 | G11: 금액
G12: 외화금액 | H12: 원화환산금액 | I12: 전월금액 | J12: 증감액
A13: Allison | B13: DSM2408-AL01 | C13: 4107224502383X | E13: 45525 | F13: =VLOOKUP(E13,환율!$A$1798:$B$2194,2,) -> 1332 | G13: 406494.08 | H13: =ROUNDDOWN(G13*F13,0) -> 541450114
B14: DSM2408-AL02 | C14: 4107224502402X | E14: 45526 | F14: =VLOOKUP(E14,환율!$A$1798:$B$2194,2,) -> 1332.4 | G14: 168424.08 | H14: =ROUNDDOWN(G14*F14,0) -> 224408244
B15: DSM2408-AL03 | C15: 4107224502517X | E15: 45534 | F15: =VLOOKUP(E15,환율!$A$1798:$B$2194,2,) -> 1335.3 | G15: 330742.14 | H15: =ROUNDDOWN(G15*F15,0) -> 441639979
B16: DSM2408-AL04 | C16: 4107224502596X | E16: 45545 | F16: =VLOOKUP(E16,환율!$A$1798:$B$2194,2,) -> 1339.5 | G16: 378904.12 | H16: =ROUNDDOWN(G16*F16,0) -> 507542068
B17: DSM2408-AL01TA | E17: 45527 | F17: =VLOOKUP(E17,환율!$A$1798:$B$2194,2,) -> 1335.9 | G17: 75600 | H17: =ROUNDDOWN(G17*F17,0) -> 100994040
B18: DSM2408-AL01TB | E18: 45527 | F18: =VLOOKUP(E18,환율!$A$1798:$B$2194,2,) -> 1335.9 | G18: 15400 | H18: =ROUNDDOWN(G18*F18,0) -> 20572860
A19: 소계 | G19: =SUM(G13:G18) -> 1375564.4 | H19: =SUM(H13:H18) -> 1836607305 | I19: 1064548801 | J19: =+H19-I19 -> 772058504
A20: Polaris | B20: 2408P01 | C20: 4107224502358X | E20: 45528 | F20: =VLOOKUP(E20,환율!$A$1798:$B$2194,2,) -> 1335.9 | G20: 73749.42 | H20: =ROUNDDOWN(G20*F20,0) -> 98521850
B21: 2408P02 | C21: 4107224502357X | E21: 45525 | F21: =VLOOKUP(E21,환율!$A$1798:$B$2194,2,) -> 1332 | G21: 34925.76 | H21: =ROUNDDOWN(G21*F21,0) -> 46521112
B22: 2408P03 | C22: 4107224502365X | E22: 45528 | F22: =VLOOKUP(E22,환율!$A$1798:$B$2194,2,) -> 1335.9 | G22: 554.27 | H22: =ROUNDDOWN(G22*F22,0) -> 740449
B23: 2408P04 | C23: 4107224502366X | E23: 45528 | F23: =VLOOKUP(E23,환율!$A$1798:$B$2194,2,) -> 1335.9 | G23: 945.12 | H23: =ROUNDDOWN(G23*F23,0) -> 1262585
B24: 2408P05 | C24: 4107224502367X | E24: 45528 | F24: =VLOOKUP(E24,환율!$A$1798:$B$2194,2,) -> 1335.9 | G24: 1438.66 | H24: =ROUNDDOWN(G24*F24,0) -> 1921905
B25: 2408P09 | C25: 4107224502464X | E25: 45527 | F25: =VLOOKUP(E25,환율!$A$1798:$B$2194,2,) -> 1335.9 | G25: 219.36 | H25: =ROUNDDOWN(G25*F25,0) -> 293043
B26: 2408P10 | C26: 4107224502480X | E26: 45527 | F26: =VLOOKUP(E26,환율!$A$1798:$B$2194,2,) -> 1335.9 | G26: 219.36 | H26: =ROUNDDOWN(G26*F26,0) -> 293043
B27: 2408P11 | C27: 4107224502481X | E27: 45527 | F27: =VLOOKUP(E27,환율!$A$1798:$B$2194,2,) -> 1335.9 | G27: 191.94 | H27: =ROUNDDOWN(G27*F27,0) -> 256412
B28: 2408P12 | C28: 4107224502506X | E28: 45531 | F28: =VLOOKUP(E28,환율!$A$1798:$B$2194,2,) -> 1323.9 | G28: 370.04 | H28: =ROUNDDOWN(G28*F28,0) -> 489895
B29: 2408P08 | C29: 4107224502492X | E29: 45536 | F29: =VLOOKUP(E29,환율!$A$1798:$B$2194,2,) -> 1335.3 | G29: 6663.3 | H29: =ROUNDDOWN(G29*F29,0) -> 8897504
A30: 소계 | G30: =SUM(G20:G29) -> 119277.23 | H30: =SUM(H20:H29) -> 159197798 | I30: 329226847 | J30: =+H30-I30 -> -170029049
A31: Mercury | B31: DSM2408-01 | C31: 4107224502360X | E31: 45526 | F31: =VLOOKUP(E31,환율!$A$1798:$B$2194,2,) -> 1332.4 | G31: 78708 | H31: =ROUNDDOWN(G31*F31,0) -> 104870539
B32: DSM2408-02 | C32: 4107224502361X | E32: 45526 | F32: =VLOOKUP(E32,환율!$A$1798:$B$2194,2,) -> 1332.4 | G32: 23786 | H32: =ROUNDDOWN(G32*F32,0) -> 31692466
B33: DSM2408-03 | C33: 4107224502415X | E33: 45534 | F33: =VLOOKUP(E33,환율!$A$1798:$B$2194,2,) -> 1335.3 | G33: 52472 | H33: =ROUNDDOWN(G33*F33,0) -> 70065861
B34: DSM2408-04 | C34: 4107224502416X | E34: 45534 | F34: =VLOOKUP(E34,환율!$A$1798:$B$2194,2,) -> 1335.3 | G34: 23786 | H34: =ROUNDDOWN(G34*F34,0) -> 31761445
B35: DSM2408-05 | C35: 4107224502417X | E35: 45530 | F35: =VLOOKUP(E35,환율!$A$1798:$B$2194,2,) -> 1340.1 | G35: 5957.16 | H35: =ROUNDDOWN(G35*F35,0) -> 7983190
B36: DSM2408-06 | C36: 4107224502491X | E36: 45535 | F36: =VLOOKUP(E36,환율!$A$1798:$B$2194,2,) -> 1335.3 | G36: 8281.6 | H36: =ROUNDDOWN(G36*F36,0) -> 11058420
B37: DSM2408-07 | C37: 4107224502490X | E37: 45542 | F37: =VLOOKUP(E37,환율!$A$1798:$B$2194,2,) -> 1335.8 | G37: 25298 | H37: =ROUNDDOWN(G37*F37,0) -> 33793068
B38: DSM2408-08 | C38: 4107224502537X | E38: 45542 | F38: =VLOOKUP(E38,환율!$A$1798:$B$2194,2,) -> 1335.8 | G38: 1575.2 | H38: =ROUNDDOWN(G38*F38,0) -> 2104152
A39: 소계 | G39: =SUM(G31:G38) -> 219863.96 | H39: =SUM(H31:H38) -> 293329141 | I39: 867380842 | J39: =+H39-I39 -> -574051701
A40: Mercury China | B40: DSM2408-MC01 | C40: 4107224502329X | E40: 45514 | F40: =VLOOKUP(E40,환율!$A$1798:$B$2194,2,) -> 1377.7 | G40: 123932.22 | H40: =ROUNDDOWN(G40*F40,0) -> 170741419
B41: DSM2408-MC02 | C41: 4107224502448X | E41: 45527 | F41: =VLOOKUP(E41,환율!$A$1798:$B$2194,2,) -> 1335.9 | G41: 105506.46 | H41: =ROUNDDOWN(G41*F41,0) -> 140946079
A42: 소계 | G42: =SUM(G40:G41) -> 229438.68 | H42: =SUM(H40:H41) -> 311687498 | I42: 316622678 | J42: =+H42-I42 -> -4935180
A43: R&R | B43: DSM2408-R01 | C43: 4107224502684X | E43: 45549 | F43: =VLOOKUP(E43,환율!$A$1798:$B$2194,2,) -> 1339.6 | G43: =H43/F43 -> 9583.3047 | H43: 12837795
B44: DSM2408-R02 | C44: 4107224502718X | E44: 45569 | F44: 1180 | G44: =H44/F44 -> 37337.434 | H44: 44058172
A45: 소계 | G45: =SUM(G43:G44) -> 46920.739 | H45: =SUM(H43:H44) -> 56895967 | I45: 68966977 | J45: =+H45-I45 -> -12071010
A46: SAM | B46: DSM2408-SM01 | C46: 4112924080087X | E46: 45523 | F46: =VLOOKUP(E46,환율!$A$1798:$B$2194,2,) -> 1360.1 | G46: 39476 | H46: =ROUNDDOWN(G46*F46,0) -> 53691307
B47: DSM2408-SM02 | C47: 4112924080148X | E47: 45530 | F47: =VLOOKUP(E47,환율!$A$1798:$B$2194,2,) -> 1340.1 | G47: 39476 | H47: =ROUNDDOWN(G47*F47,0) -> 52901787
B48: DSM2405-SM01 | C48: 4112924050134X | D48: 45419 | E48: 45434 | F48: =VLOOKUP(E48,환율!$A$1798:$B$2033,2,) -> 1364.4 | G48: 13816.6 | H48: -20148488 | I48: 2023 ~ 소재각인, 기포, 소재떨어짐 불량 13EA
A49: 소계 | G49: =SUM(G46:G48) -> 92768.6 | H49: =SUM(H46:H48) -> 86444606 | I49: 54480827 | J49: =+H49-I49 -> 31963779
...

Sheet 24.09 (갑)
A6: ※ 2024년 9월 마감내역 ※
A11: 거래처 | B11: Invoice | C11: 면장번호 | D11: 인보이스 날짜 | E11: BL일자 | F11: 환율 | G11: 금액
G12: 외화금액 | H12: 원화환산금액 | I12: 전월금액 | J12: 증감액
A13: Allison | B13: DSM2409-AL01 | C13: 4107224502683X | E13: 45552 | F13: =VLOOKUP(E13,환율!$A$1798:$B$2194,2,) -> 1339.6 | G13: 411621 | H13: =ROUNDDOWN(G13*F13,0) -> 551407491
B14: DSM2409-AL02 | C14: 4107224502741X | E14: 45567 | F14: =VLOOKUP(E14,환율!$A$1798:$B$2194,2,) -> 1306.9 | G14: 356990.55 | H14: =ROUNDDOWN(G14*F14,0) -> 466550949
B15: DSM2409-AL03 | C15: 4107224502790X | E15: 45572 | F15: =VLOOKUP(E15,환율!$A$1798:$B$2194,2,) -> 1333.3 | G15: 372967.57 | H15: =ROUNDDOWN(G15*F15,0) -> 497277661
A16: 소계 | G16: =SUM(G13:G15) -> 1141579.1 | H16: =SUM(H13:H15) -> 1515236101 | I16: 1836607305 | J16: =+H16-I16 -> -321371204
A17: Polaris | B17: 2409P01 | C17: 4107224502543X | E17: 45551 | F17: =VLOOKUP(E17,환율!$A$1798:$B$2194,2,) -> 1339.6 | G17: 94251.84 | H17: =ROUNDDOWN(G17*F17,0) -> 126259764
B18: 2409P02 | C18: 4107224502545X | E18: 45547 | F18: =VLOOKUP(E18,환율!$A$1798:$B$2194,2,) -> 1340.3 | G18: 16470.72 | H18: =ROUNDDOWN(G18*F18,0) -> 22075706
B19: 2409P05 | C19: 4107224502641X | E19: 45551 | F19: =VLOOKUP(E19,환율!$A$1798:$B$2194,2,) -> 1339.6 | G19: 1837.44 | H19: =ROUNDDOWN(G19*F19,0) -> 2461434
B20: 2409P06 | C20: 4107224502700X | E20: 45565 | F20: =VLOOKUP(E20,환율!$A$1798:$B$2194,2,) -> 1319.6 | G20: 13072.32 | H20: =ROUNDDOWN(G20*F20,0) -> 17250233
B21: 2409P03 | C21: 4107224502544X | E21: 45567 | F21: =VLOOKUP(E21,환율!$A$1798:$B$2194,2,) -> 1306.9 | G21: 29115.6 | H21: =ROUNDDOWN(G21*F21,0) -> 38051177
B22: 2409P04 | C22: 4107224502701X | E22: 45569 | F22: =VLOOKUP(E22,환율!$A$1798:$B$2194,2,) -> 1320.1 | G22: 18470.88 | H22: =ROUNDDOWN(G22*F22,0) -> 24383408
B23: 2409SCP | E23: 45537 | F23: =VLOOKUP(E23,환율!$A$1798:$B$2194,2,) -> 1334.8 | G23: 26459.73 | H23: =ROUNDDOWN(G23*F23,0) -> 35318447
A24: 소계 | G24: =SUM(G17:G23) -> 199678.53 | H24: =SUM(H17:H23) -> 265800169 | I24: 159197798 | J24: =+H24-I24 -> 106602371
A25: Mercury | B25: DSM2409-02 | C25: 4107224502720X | E25: 45560 | F25: =VLOOKUP(E25,환율!$A$1798:$B$2194,2,) -> 1334.3 | G25: 3696.07 | H25: =ROUNDDOWN(G25*F25,0) -> 4931666
B26: DSM2409-01 | C26: 4107224502815X | E26: 45579 | F26: =VLOOKUP(E26,환율!$A$1798:$B$2194,2,) -> 1348.6 | G26: 6947.5 | H26: =ROUNDDOWN(G26*F26,0) -> 9369398
A27: 소계 | G27: =SUM(G25:G26) -> 10643.57 | H27: =SUM(H25:H26) -> 14301064 | I27: 293329141 | J27: =+H27-I27 -> -279028077
A28: Mercury China | B28: DSM2409-MC01 | C28: 4107224502567X | E28: 45542 | F28: =VLOOKUP(E28,환율!$A$1798:$B$2194,2,) -> 1335.8 | G28: 114775.02 | H28: =ROUNDDOWN(G28*F28,0) -> 153316471
B29: DSM2409-MC02 | C29: 4107224502688X | E29: 45557 | F29: =VLOOKUP(E29,환율!$A$1798:$B$2194,2,) -> 1331.8 | G29: 110301.36 | H29: =ROUNDDOWN(G29*F29,0) -> 146899351
B30: DSM2409-MC03 | C30: 4107224502799X | E30: 45573 | F30: =VLOOKUP(E30,환율!$A$1798:$B$2194,2,) -> 1346.5 | G30: 125360.94 | H30: =ROUNDDOWN(G30*F30,0) -> 168798505
A31: 소계 | G31: =SUM(G28:G29) -> 225076.38 | H31: =SUM(H28:H30) -> 469014327 | I31: 311687498 | J31: =+H31-I31 -> 157326829
A32: R&R | B32: DSM2409-R01 | C32: 4107224502914X | E32: 45580 | F32: =VLOOKUP(E32,환율!$A$1798:$B$2194,2,) -> 1354.9 | G32: =H32/F32 -> 3719.3889 | H32: 5039400
B33: DSM2409-R02 | C33: 4107224502991X | E33: 45596 | F33: =VLOOKUP(E33,환율!$A$1798:$B$2194,2,) -> 1383.3 | G33: =H33/F33 -> 34030.622 | H33: 47074560
A34: 소계 | G34: =SUM(G32:G33) -> 37750.011 | H34: =SUM(H32:H33) -> 52113960 | I34: 56895967 | J34: =+H34-I34 -> -4782007
A35: SAM | B35: DSM2409-SM01 | C35: 4112924090033X | E35: 45546 | F35: =VLOOKUP(E35,환율!$A$1798:$B$2194,2,) -> 1344.3 | G35: 39476 | H35: =ROUNDDOWN(G35*F35,0) -> 53067586
A36: 소계 | G36: =SUM(G35:G35) -> 39476 | H36: =SUM(H35:H35) -> 53067586 | I36: 86444606 | J36: =+H36-I36 -> -33377020
A37: SEASTAR | B37: DSM2409-SE01 | C37: 4107224502681X | E37: 45567 | F37: =VLOOKUP(E37,환율!$A$1798:$B$2194,2,) -> 1306.9 | G37: 11039.8 | H37: =ROUNDDOWN(G37*F37,0) -> 14427914
A38: 소계 | G38: =SUM(G37:G37) -> 11039.8 | H38: =SUM(H37:H37) -> 14427914 | I38: =SUM(I37:I37) -> 0 | J38: =+H38-I38 -> 14427914
A39: Emerson | B39: DSM2409-EM01 | C39: 4107224201692X | E39: 45545 | F39: =VLOOKUP(E39,환율!$A$1798:$B$2194,2,) -> 1339.5 | G39: 5394.24 | H39: =ROUNDDOWN(G39*F39,0) -> 7225584
B40: DSM2409-EM02 | C40: 4107224201681X | E40: 45536 | F40: =VLOOKUP(E40,환율!$A$1798:$B$2194,2,) -> 1335.3 | G40: 1636.5 | H40: =ROUNDDOWN(G40*F40,0) -> 2185218
B41: DSM2409-EM03 | C41: 4107224502588X | E41: 45545 | F41: =VLOOKUP(E41,환율!$A$1798:$B$2194,2,) -> 1339.5 | G41: 17586.01 | H41: =ROUNDDOWN(G41*F41,0) -> 23556460
B42: DSM2409-EM04 | C42: 4107224502559X | E42: 45543 | F42: =VLOOKUP(E42,환율!$A$1798:$B$2194,2,) -> 1335.8 | G42: 2564.46 | H42: =ROUNDDOWN(G42*F42,0) -> 3425605
B43: DSM2409-EM05 | C43: 4107224201767X | E43: 45550 | F43: =VLOOKUP(E43,환율!$A$1798:$B$2194,2,) -> 1339.6 | G43: 37501 | H43: =ROUNDDOWN(G43*F43,0) -> 50236339
B44: DSM2409-EM06 | C44: 4107224502605X | E44: 45551 | F44: =VLOOKUP(E44,환율!$A$1798:$B$2194,2,) -> 1339.6 | G44: 3354.78 | H44: =ROUNDDOWN(G44*F44,0) -> 4494063
B45: DSM2409-EM07 | C45: 4107224502606X | E45: 45545 | F45: =VLOOKUP(E45,환율!$A$1798:$B$2194,2,) -> 1339.5 | G45: 282.04 | H45: =ROUNDDOWN(G45*F45,0) -> 377792
B46: DSM2409-EM10 | C46: 4107224502734X | E46: 45561 | F46: =VLOOKUP(E46,환율!$A$1798:$B$2194,2,) -> 1328.4 | G46: 511.1 | H46: =ROUNDDOWN(G46*F46,0) -> 678945 | K46: DSM2409-EM09는 이전에 제가 아랍으로 물건을 잘못 더 보내서 실제 출하는 안했고 인보이스만 만들었어요!
B47: DSM2409-EM12 | E47: 45555 | F47: =VLOOKUP(E47,환율!$A$1798:$B$2194,2,) -> 1331.8 | G47: 7630 | H47: =ROUNDDOWN(G47*F47,0) -> 10161634
A48: 소계 | G48: =SUM(G39:G47) -> 76460.13 | H48: =SUM(H39:H47) -> 102341640 | I48: 99788204 | J48: =+H48-I48 -> 2553436
A49: AMAT | B49: DSM2409-AM01 | C49: 2057624090227X | E49: 45554 | F49: =VLOOKUP(E49,환율!$A$1798:$B$2194,2,) -> 1331 | G49: 10642.14 | H49: =ROUNDDOWN(G49*F49,0) -> 14164688
...

Sheet 24.10 (갑)
A6: ※ 2024년 10월 마감내역 ※
A11: 거래처 | B11: Invoice | C11: 면장번호 | D11: 인보이스 날짜 | E11: BL일자 | F11: 환율 | G11: 금액
G12: 외화금액 | H12: 원화환산금액 | I12: 전월금액 | J12: 증감액
A13: Allison | B13: DSM2410-AL01 | C13: 4107224502871X | E13: 45581 | F13: =VLOOKUP(E13,환율!$A$1798:$B$2194,2,) -> 1360.4 | G13: 390570.69 | H13: =ROUNDDOWN(G13*F13,0) -> 531332366
B14: DSM2410-AL02 | C14: 4107224202101X | E14: 45588 | F14: =VLOOKUP(E14,환율!$A$1798:$B$2194,2,) -> 1380.1 | G14: 393323.59 | H14: =ROUNDDOWN(G14*F14,0) -> 542825886
B15: DSM2410-AL03 | C15: 4107224503049X | E15: 45603 | F15: =VLOOKUP(E15,환율!$A$1798:$B$2194,2,) -> 1391.5 | G15: 364428.65 | H15: =ROUNDDOWN(G15*F15,0) -> 507102466
B16: DSM2410-AL01TC | E16: 45588 | F16: =VLOOKUP(E16,환율!$A$1798:$B$2194,2,) -> 1380.1 | G16: 69000 | H16: =ROUNDDOWN(G16*F16,0) -> 95226900
A17: 소계 | G17: =SUM(G13:G16) -> 1217322.9 | H17: =SUM(H13:H16) -> 1676487618 | I17: 1515236101 | J17: =+H17-I17 -> 161251517
A18: Polaris | B18: 2410P01 | C18: 4107224502778X | E18: 45571 | F18: =VLOOKUP(E18,환율!$A$1798:$B$2194,2,) -> 1320.1 | G18: 58466.88 | H18: =ROUNDDOWN(G18*F18,0) -> 77182128
B19: 2410P02 | C19: 4107224502779X | E19: 45571 | F19: =VLOOKUP(E19,환율!$A$1798:$B$2194,2,) -> 1320.1 | G19: 109.6 | H19: =ROUNDDOWN(G19*F19,0) -> 144682
B20: 2410P03 | C20: 4107224502780X | E20: 45571 | F20: =VLOOKUP(E20,환율!$A$1798:$B$2194,2,) -> 1320.1 | G20: 726.88 | H20: =ROUNDDOWN(G20*F20,0) -> 959554
B21: 2410P04 | C21: 4107224502867X | E21: 45586 | F21: =VLOOKUP(E21,환율!$A$1798:$B$2194,2,) -> 1371.1 | G21: 6386.88 | H21: =ROUNDDOWN(G21*F21,0) -> 8757051
B22: 2410P06 | C22: 4107224502874X | E22: 45584 | F22: =VLOOKUP(E22,환율!$A$1798:$B$2194,2,) -> 1366.5 | G22: 13348.8 | H22: =ROUNDDOWN(G22*F22,0) -> 18241135
B23: 2410P05 | C23: 4107224502920X | E23: 45603 | F23: =VLOOKUP(E23,환율!$A$1798:$B$2194,2,) -> 1391.5 | G23: 21430.08 | H23: =ROUNDDOWN(G23*F23,0) -> 29819956
B24: 2410P07 | C24: 4107224502969X | E24: 45603 | F24: =VLOOKUP(E24,환율!$A$1798:$B$2194,2,) -> 1391.5 | G24: 64822.86 | H24: =ROUNDDOWN(G24*F24,0) -> 90201009
B25: 2410P08 | C25: 4107224503030X | E25: 45604 | F25: =VLOOKUP(E25,환율!$A$1798:$B$2194,2,) -> 1399.1 | G25: 18190.8 | H25: =ROUNDDOWN(G25*F25,0) -> 25450748
A26: 소계 | G26: =SUM(G18:G25) -> 183482.78 | H26: =SUM(H18:H25) -> 250756263 | I26: 265800169 | J26: =+H26-I26 -> -15043906
A27: Mercury | B27: DSM2410-01 | C27: 4107224502963X | E27: 45590 | F27: =VLOOKUP(E27,환율!$A$1798:$B$2194,2,) -> 1380.5 | G27: 3251.43 | H27: =ROUNDDOWN(G27*F27,0) -> 4488599
B28: DSM2410-PS01 | C28: 4107224502868X | E28: 45573 | F28: =VLOOKUP(E28,환율!$A$1798:$B$2194,2,) -> 1346.5 | G28: 524.72 | H28: =ROUNDDOWN(G28*F28,0) -> 706535
B29: DSM2410-02 | C29: 4107224503013X | E29: 45600 | F29: =VLOOKUP(E29,환율!$A$1798:$B$2194,2,) -> 1377.9 | G29: 3225.6 | H29: =ROUNDDOWN(G29*F29,0) -> 4444554
B30: DSM2410-03 | C30: 4107224503014X | E30: 45600 | F30: =VLOOKUP(E30,환율!$A$1798:$B$2194,2,) -> 1377.9 | G30: 1928.6 | H30: =ROUNDDOWN(G30*F30,0) -> 2657417
B31: DSM2410-04 | C31: 4107224503054X | E31: 45605 | F31: =VLOOKUP(E31,환율!$A$1798:$B$2194,2,) -> 1399.1 | G31: 105993.44 | H31: =ROUNDDOWN(G31*F31,0) -> 148295421
A32: 소계 | G32: =SUM(G27:G31) -> 114923.79 | H32: =SUM(H27:H31) -> 160592526 | I32: 14301064 | J32: =+H32-I32 -> 146291462
A33: Mercury China | B33: DSM2410-MC01 | C33: 4107224502939X | E33: 45584 | F33: =VLOOKUP(E33,환율!$A$1798:$B$2194,2,) -> 1366.5 | G33: 127343.82 | H33: =ROUNDDOWN(G33*F33,0) -> 174015330
A34: 소계 | G34: =SUM(G33:G33) -> 127343.82 | H34: =SUM(H33:H33) -> 174015330 | I34: 469014327 | J34: =+H34-I34 -> -294998997
B35: DSM2410-R01 | C35: 4107224503339X | E35: 45623 | F35: =VLOOKUP(E35,환율!$A$1798:$B$2194,2,) -> 1401.2 | G35: =H35/F35 -> 11136.8 | H35: 15604884
B36: DSM2410-R02 | C36: 4107224503246X | E36: 45618 | F36: =VLOOKUP(E36,환율!$A$1798:$B$2194,2,) -> 1398.1 | G36: =H36/F36 -> 21760.169 | H36: 30422892
A37: 소계 | G37: =SUM(G35:G36) -> 32896.969 | H37: =SUM(H35:H36) -> 46027776 | I37: 52113960 | J37: =+H37-I37 -> -6086184
A38: SAM | B38: DSM2410-SM01 | C38: 4112924100067X | E38: 45583 | F38: =VLOOKUP(E38,환율!$A$1798:$B$2194,2,) -> 1366.5 | G38: 39476 | H38: =ROUNDDOWN(G38*F38,0) -> 53943954
B39: DSM2410-SM02 | C39: 4112924100268X | E39: 45607 | F39: =VLOOKUP(E39,환율!$A$1798:$B$2194,2,) -> 1385.4 | G39: 39476 | H39: =ROUNDDOWN(G39*F39,0) -> 54690050
